[2018-05-25 16:51:10,091][Thread-1:3476][task_id:collect][views.py:282][INFO][得到年和月的参数啦！！！！]
[2018-05-25 16:54:36,822][Thread-1:7356][task_id:django.request][exception.py:135][ERROR][Internal Server Error: /blog/xiaohei/archive/2018x05/]
Traceback (most recent call last):
  File "C:\Python36\lib\site-packages\django\core\handlers\exception.py", line 41, in inner
    response = get_response(request)
  File "C:\Python36\lib\site-packages\django\core\handlers\base.py", line 187, in _get_response
    response = self.process_exception_by_middleware(e, request)
  File "C:\Python36\lib\site-packages\django\core\handlers\base.py", line 185, in _get_response
    response = wrapped_callback(request, *callback_args, **callback_kwargs)
  File "D:\python10\day78\bbs\blog\views.py", line 281, in home
    year, month = args[1].split("-")
ValueError: not enough values to unpack (expected 2, got 1)
[2018-05-25 16:56:32,723][Thread-1:8112][task_id:blog.views][views.py:290][ERROR][请求访问的日期归档格式不正确！！！]
[2018-05-25 16:56:39,854][Thread-3:6132][task_id:django.request][exception.py:135][ERROR][Internal Server Error: /blog/xiaohei/archive/2018-05-/]
Traceback (most recent call last):
  File "C:\Python36\lib\site-packages\django\core\handlers\exception.py", line 41, in inner
    response = get_response(request)
  File "C:\Python36\lib\site-packages\django\core\handlers\base.py", line 187, in _get_response
    response = self.process_exception_by_middleware(e, request)
  File "C:\Python36\lib\site-packages\django\core\handlers\base.py", line 185, in _get_response
    response = wrapped_callback(request, *callback_args, **callback_kwargs)
  File "D:\python10\day78\bbs\blog\views.py", line 282, in home
    year, month = args[1].split("-")
ValueError: too many values to unpack (expected 2)
[2018-05-25 16:57:44,421][Thread-1:5596][task_id:blog.views][views.py:290][WARNING][请求访问的日期归档格式不正确！！！]
[2018-05-25 16:57:44,421][Thread-1:5596][task_id:blog.views][views.py:291][WARNING][too many values to unpack (expected 2)]
[2018-05-28 08:41:53,683][Thread-11:6448][task_id:django.request][base.py:152][WARNING][Not Found: /favicon.ico]
[2018-05-28 08:42:19,143][Thread-13:6564][task_id:django.request][base.py:152][WARNING][Not Found: /blog/]
[2018-05-28 10:12:02,507][Thread-186:7096][task_id:requests.packages.urllib3.connectionpool][connectionpool.py:214][INFO][Starting new HTTP connection (1): api.geetest.com]
[2018-05-28 10:12:23,218][Thread-188:2116][task_id:requests.packages.urllib3.connectionpool][connectionpool.py:214][INFO][Starting new HTTP connection (1): api.geetest.com]
[2018-05-28 10:32:54,986][Thread-12:6200][task_id:django.security.csrf][csrf.py:160][WARNING][Forbidden (CSRF token missing or incorrect.): /blog/up_down]
[2018-05-28 10:35:21,048][Thread-33:192][task_id:blog.views][views.py:249][WARNING][又有人访问不存在页面了...]
[2018-05-28 10:47:42,388][Thread-12:5696][task_id:django.request][exception.py:135][ERROR][Internal Server Error: /blog/up_down/]
Traceback (most recent call last):
  File "C:\Python36\lib\site-packages\django\core\handlers\exception.py", line 41, in inner
    response = get_response(request)
  File "C:\Python36\lib\site-packages\django\core\handlers\base.py", line 187, in _get_response
    response = self.process_exception_by_middleware(e, request)
  File "C:\Python36\lib\site-packages\django\core\handlers\base.py", line 185, in _get_response
    response = wrapped_callback(request, *callback_args, **callback_kwargs)
  File "D:\python10\day78\bbs\blog\views.py", line 349, in up_down
    models.ArticleUpDown.objects.create(user=user,article_id=article_id,is_up=is_up)
  File "C:\Python36\lib\site-packages\django\db\models\manager.py", line 85, in manager_method
    return getattr(self.get_queryset(), name)(*args, **kwargs)
  File "C:\Python36\lib\site-packages\django\db\models\query.py", line 392, in create
    obj = self.model(**kwargs)
  File "C:\Python36\lib\site-packages\django\db\models\base.py", line 555, in __init__
    _setattr(self, field.name, rel_obj)
  File "C:\Python36\lib\site-packages\django\db\models\fields\related_descriptors.py", line 216, in __set__
    self.field.remote_field.model._meta.object_name,
ValueError: Cannot assign "<SimpleLazyObject: <django.contrib.auth.models.AnonymousUser object at 0x000000000BDAE9B0>>": "ArticleUpDown.user" must be a "UserInfo" instance.
[2018-05-28 10:49:05,554][Thread-20:7108][task_id:requests.packages.urllib3.connectionpool][connectionpool.py:214][INFO][Starting new HTTP connection (1): api.geetest.com]
[2018-05-28 10:49:22,398][Thread-21:3816][task_id:requests.packages.urllib3.connectionpool][connectionpool.py:214][INFO][Starting new HTTP connection (1): api.geetest.com]
[2018-05-29 08:38:27,049][Thread-8:7120][task_id:django.request][base.py:152][WARNING][Not Found: /favicon.ico]
[2018-05-29 08:55:22,891][Thread-21:1380][task_id:django.request][exception.py:135][ERROR][Internal Server Error: /blog/up_down/]
Traceback (most recent call last):
  File "D:\python10\day78\bbs\blog\views.py", line 352, in up_down
    models.ArticleUpDown.objects.create(user=user,article_id=article_id,is_up=is_up)
  File "C:\Python36\lib\site-packages\django\db\models\manager.py", line 85, in manager_method
    return getattr(self.get_queryset(), name)(*args, **kwargs)
  File "C:\Python36\lib\site-packages\django\db\models\query.py", line 394, in create
    obj.save(force_insert=True, using=self.db)
  File "C:\Python36\lib\site-packages\django\db\models\base.py", line 808, in save
    force_update=force_update, update_fields=update_fields)
  File "C:\Python36\lib\site-packages\django\db\models\base.py", line 838, in save_base
    updated = self._save_table(raw, cls, force_insert, force_update, using, update_fields)
  File "C:\Python36\lib\site-packages\django\db\models\base.py", line 924, in _save_table
    result = self._do_insert(cls._base_manager, using, fields, update_pk, raw)
  File "C:\Python36\lib\site-packages\django\db\models\base.py", line 963, in _do_insert
    using=using, raw=raw)
  File "C:\Python36\lib\site-packages\django\db\models\manager.py", line 85, in manager_method
    return getattr(self.get_queryset(), name)(*args, **kwargs)
  File "C:\Python36\lib\site-packages\django\db\models\query.py", line 1076, in _insert
    return query.get_compiler(using=using).execute_sql(return_id)
  File "C:\Python36\lib\site-packages\django\db\models\sql\compiler.py", line 1106, in execute_sql
    for sql, params in self.as_sql():
  File "C:\Python36\lib\site-packages\django\db\models\sql\compiler.py", line 1059, in as_sql
    for obj in self.query.objs
  File "C:\Python36\lib\site-packages\django\db\models\sql\compiler.py", line 1059, in <listcomp>
    for obj in self.query.objs
  File "C:\Python36\lib\site-packages\django\db\models\sql\compiler.py", line 1058, in <listcomp>
    [self.prepare_value(field, self.pre_save_val(field, obj)) for field in fields]
  File "C:\Python36\lib\site-packages\django\db\models\sql\compiler.py", line 998, in prepare_value
    value = field.get_db_prep_save(value, connection=self.connection)
  File "C:\Python36\lib\site-packages\django\db\models\fields\related.py", line 963, in get_db_prep_save
    return self.target_field.get_db_prep_save(value, connection=connection)
  File "C:\Python36\lib\site-packages\django\db\models\fields\__init__.py", line 770, in get_db_prep_save
    prepared=False)
  File "C:\Python36\lib\site-packages\django\db\models\fields\__init__.py", line 958, in get_db_prep_value
    value = self.get_prep_value(value)
  File "C:\Python36\lib\site-packages\django\db\models\fields\__init__.py", line 966, in get_prep_value
    return int(value)
ValueError: invalid literal for int() with base 10: '{{ article.pk }}'

During handling of the above exception, another exception occurred:

Traceback (most recent call last):
  File "C:\Python36\lib\site-packages\django\core\handlers\exception.py", line 41, in inner
    response = get_response(request)
  File "C:\Python36\lib\site-packages\django\core\handlers\base.py", line 187, in _get_response
    response = self.process_exception_by_middleware(e, request)
  File "C:\Python36\lib\site-packages\django\core\handlers\base.py", line 185, in _get_response
    response = wrapped_callback(request, *callback_args, **callback_kwargs)
  File "D:\python10\day78\bbs\blog\views.py", line 357, in up_down
    response["fisrt_action"]=models.ArticleUpDown.objects.filter(user=user,article_id=article_id).first().is_up
  File "C:\Python36\lib\site-packages\django\db\models\manager.py", line 85, in manager_method
    return getattr(self.get_queryset(), name)(*args, **kwargs)
  File "C:\Python36\lib\site-packages\django\db\models\query.py", line 784, in filter
    return self._filter_or_exclude(False, *args, **kwargs)
  File "C:\Python36\lib\site-packages\django\db\models\query.py", line 802, in _filter_or_exclude
    clone.query.add_q(Q(*args, **kwargs))
  File "C:\Python36\lib\site-packages\django\db\models\sql\query.py", line 1250, in add_q
    clause, _ = self._add_q(q_object, self.used_aliases)
  File "C:\Python36\lib\site-packages\django\db\models\sql\query.py", line 1276, in _add_q
    allow_joins=allow_joins, split_subq=split_subq,
  File "C:\Python36\lib\site-packages\django\db\models\sql\query.py", line 1206, in build_filter
    condition = lookup_class(lhs, value)
  File "C:\Python36\lib\site-packages\django\db\models\lookups.py", line 24, in __init__
    self.rhs = self.get_prep_lookup()
  File "C:\Python36\lib\site-packages\django\db\models\fields\related_lookups.py", line 112, in get_prep_lookup
    self.rhs = target_field.get_prep_value(self.rhs)
  File "C:\Python36\lib\site-packages\django\db\models\fields\__init__.py", line 966, in get_prep_value
    return int(value)
ValueError: invalid literal for int() with base 10: '{{ article.pk }}'
[2018-05-29 08:55:24,182][Thread-22:6636][task_id:django.request][exception.py:135][ERROR][Internal Server Error: /blog/up_down/]
Traceback (most recent call last):
  File "D:\python10\day78\bbs\blog\views.py", line 352, in up_down
    models.ArticleUpDown.objects.create(user=user,article_id=article_id,is_up=is_up)
  File "C:\Python36\lib\site-packages\django\db\models\manager.py", line 85, in manager_method
    return getattr(self.get_queryset(), name)(*args, **kwargs)
  File "C:\Python36\lib\site-packages\django\db\models\query.py", line 394, in create
    obj.save(force_insert=True, using=self.db)
  File "C:\Python36\lib\site-packages\django\db\models\base.py", line 808, in save
    force_update=force_update, update_fields=update_fields)
  File "C:\Python36\lib\site-packages\django\db\models\base.py", line 838, in save_base
    updated = self._save_table(raw, cls, force_insert, force_update, using, update_fields)
  File "C:\Python36\lib\site-packages\django\db\models\base.py", line 924, in _save_table
    result = self._do_insert(cls._base_manager, using, fields, update_pk, raw)
  File "C:\Python36\lib\site-packages\django\db\models\base.py", line 963, in _do_insert
    using=using, raw=raw)
  File "C:\Python36\lib\site-packages\django\db\models\manager.py", line 85, in manager_method
    return getattr(self.get_queryset(), name)(*args, **kwargs)
  File "C:\Python36\lib\site-packages\django\db\models\query.py", line 1076, in _insert
    return query.get_compiler(using=using).execute_sql(return_id)
  File "C:\Python36\lib\site-packages\django\db\models\sql\compiler.py", line 1106, in execute_sql
    for sql, params in self.as_sql():
  File "C:\Python36\lib\site-packages\django\db\models\sql\compiler.py", line 1059, in as_sql
    for obj in self.query.objs
  File "C:\Python36\lib\site-packages\django\db\models\sql\compiler.py", line 1059, in <listcomp>
    for obj in self.query.objs
  File "C:\Python36\lib\site-packages\django\db\models\sql\compiler.py", line 1058, in <listcomp>
    [self.prepare_value(field, self.pre_save_val(field, obj)) for field in fields]
  File "C:\Python36\lib\site-packages\django\db\models\sql\compiler.py", line 998, in prepare_value
    value = field.get_db_prep_save(value, connection=self.connection)
  File "C:\Python36\lib\site-packages\django\db\models\fields\related.py", line 963, in get_db_prep_save
    return self.target_field.get_db_prep_save(value, connection=connection)
  File "C:\Python36\lib\site-packages\django\db\models\fields\__init__.py", line 770, in get_db_prep_save
    prepared=False)
  File "C:\Python36\lib\site-packages\django\db\models\fields\__init__.py", line 958, in get_db_prep_value
    value = self.get_prep_value(value)
  File "C:\Python36\lib\site-packages\django\db\models\fields\__init__.py", line 966, in get_prep_value
    return int(value)
ValueError: invalid literal for int() with base 10: '{{ article.pk }}'

During handling of the above exception, another exception occurred:

Traceback (most recent call last):
  File "C:\Python36\lib\site-packages\django\core\handlers\exception.py", line 41, in inner
    response = get_response(request)
  File "C:\Python36\lib\site-packages\django\core\handlers\base.py", line 187, in _get_response
    response = self.process_exception_by_middleware(e, request)
  File "C:\Python36\lib\site-packages\django\core\handlers\base.py", line 185, in _get_response
    response = wrapped_callback(request, *callback_args, **callback_kwargs)
  File "D:\python10\day78\bbs\blog\views.py", line 357, in up_down
    response["fisrt_action"]=models.ArticleUpDown.objects.filter(user=user,article_id=article_id).first().is_up
  File "C:\Python36\lib\site-packages\django\db\models\manager.py", line 85, in manager_method
    return getattr(self.get_queryset(), name)(*args, **kwargs)
  File "C:\Python36\lib\site-packages\django\db\models\query.py", line 784, in filter
    return self._filter_or_exclude(False, *args, **kwargs)
  File "C:\Python36\lib\site-packages\django\db\models\query.py", line 802, in _filter_or_exclude
    clone.query.add_q(Q(*args, **kwargs))
  File "C:\Python36\lib\site-packages\django\db\models\sql\query.py", line 1250, in add_q
    clause, _ = self._add_q(q_object, self.used_aliases)
  File "C:\Python36\lib\site-packages\django\db\models\sql\query.py", line 1276, in _add_q
    allow_joins=allow_joins, split_subq=split_subq,
  File "C:\Python36\lib\site-packages\django\db\models\sql\query.py", line 1206, in build_filter
    condition = lookup_class(lhs, value)
  File "C:\Python36\lib\site-packages\django\db\models\lookups.py", line 24, in __init__
    self.rhs = self.get_prep_lookup()
  File "C:\Python36\lib\site-packages\django\db\models\fields\related_lookups.py", line 112, in get_prep_lookup
    self.rhs = target_field.get_prep_value(self.rhs)
  File "C:\Python36\lib\site-packages\django\db\models\fields\__init__.py", line 966, in get_prep_value
    return int(value)
ValueError: invalid literal for int() with base 10: '{{ article.pk }}'
[2018-05-29 08:55:25,009][Thread-23:7120][task_id:django.request][exception.py:135][ERROR][Internal Server Error: /blog/up_down/]
Traceback (most recent call last):
  File "D:\python10\day78\bbs\blog\views.py", line 352, in up_down
    models.ArticleUpDown.objects.create(user=user,article_id=article_id,is_up=is_up)
  File "C:\Python36\lib\site-packages\django\db\models\manager.py", line 85, in manager_method
    return getattr(self.get_queryset(), name)(*args, **kwargs)
  File "C:\Python36\lib\site-packages\django\db\models\query.py", line 394, in create
    obj.save(force_insert=True, using=self.db)
  File "C:\Python36\lib\site-packages\django\db\models\base.py", line 808, in save
    force_update=force_update, update_fields=update_fields)
  File "C:\Python36\lib\site-packages\django\db\models\base.py", line 838, in save_base
    updated = self._save_table(raw, cls, force_insert, force_update, using, update_fields)
  File "C:\Python36\lib\site-packages\django\db\models\base.py", line 924, in _save_table
    result = self._do_insert(cls._base_manager, using, fields, update_pk, raw)
  File "C:\Python36\lib\site-packages\django\db\models\base.py", line 963, in _do_insert
    using=using, raw=raw)
  File "C:\Python36\lib\site-packages\django\db\models\manager.py", line 85, in manager_method
    return getattr(self.get_queryset(), name)(*args, **kwargs)
  File "C:\Python36\lib\site-packages\django\db\models\query.py", line 1076, in _insert
    return query.get_compiler(using=using).execute_sql(return_id)
  File "C:\Python36\lib\site-packages\django\db\models\sql\compiler.py", line 1106, in execute_sql
    for sql, params in self.as_sql():
  File "C:\Python36\lib\site-packages\django\db\models\sql\compiler.py", line 1059, in as_sql
    for obj in self.query.objs
  File "C:\Python36\lib\site-packages\django\db\models\sql\compiler.py", line 1059, in <listcomp>
    for obj in self.query.objs
  File "C:\Python36\lib\site-packages\django\db\models\sql\compiler.py", line 1058, in <listcomp>
    [self.prepare_value(field, self.pre_save_val(field, obj)) for field in fields]
  File "C:\Python36\lib\site-packages\django\db\models\sql\compiler.py", line 998, in prepare_value
    value = field.get_db_prep_save(value, connection=self.connection)
  File "C:\Python36\lib\site-packages\django\db\models\fields\related.py", line 963, in get_db_prep_save
    return self.target_field.get_db_prep_save(value, connection=connection)
  File "C:\Python36\lib\site-packages\django\db\models\fields\__init__.py", line 770, in get_db_prep_save
    prepared=False)
  File "C:\Python36\lib\site-packages\django\db\models\fields\__init__.py", line 958, in get_db_prep_value
    value = self.get_prep_value(value)
  File "C:\Python36\lib\site-packages\django\db\models\fields\__init__.py", line 966, in get_prep_value
    return int(value)
ValueError: invalid literal for int() with base 10: '{{ article.pk }}'

During handling of the above exception, another exception occurred:

Traceback (most recent call last):
  File "C:\Python36\lib\site-packages\django\core\handlers\exception.py", line 41, in inner
    response = get_response(request)
  File "C:\Python36\lib\site-packages\django\core\handlers\base.py", line 187, in _get_response
    response = self.process_exception_by_middleware(e, request)
  File "C:\Python36\lib\site-packages\django\core\handlers\base.py", line 185, in _get_response
    response = wrapped_callback(request, *callback_args, **callback_kwargs)
  File "D:\python10\day78\bbs\blog\views.py", line 357, in up_down
    response["fisrt_action"]=models.ArticleUpDown.objects.filter(user=user,article_id=article_id).first().is_up
  File "C:\Python36\lib\site-packages\django\db\models\manager.py", line 85, in manager_method
    return getattr(self.get_queryset(), name)(*args, **kwargs)
  File "C:\Python36\lib\site-packages\django\db\models\query.py", line 784, in filter
    return self._filter_or_exclude(False, *args, **kwargs)
  File "C:\Python36\lib\site-packages\django\db\models\query.py", line 802, in _filter_or_exclude
    clone.query.add_q(Q(*args, **kwargs))
  File "C:\Python36\lib\site-packages\django\db\models\sql\query.py", line 1250, in add_q
    clause, _ = self._add_q(q_object, self.used_aliases)
  File "C:\Python36\lib\site-packages\django\db\models\sql\query.py", line 1276, in _add_q
    allow_joins=allow_joins, split_subq=split_subq,
  File "C:\Python36\lib\site-packages\django\db\models\sql\query.py", line 1206, in build_filter
    condition = lookup_class(lhs, value)
  File "C:\Python36\lib\site-packages\django\db\models\lookups.py", line 24, in __init__
    self.rhs = self.get_prep_lookup()
  File "C:\Python36\lib\site-packages\django\db\models\fields\related_lookups.py", line 112, in get_prep_lookup
    self.rhs = target_field.get_prep_value(self.rhs)
  File "C:\Python36\lib\site-packages\django\db\models\fields\__init__.py", line 966, in get_prep_value
    return int(value)
ValueError: invalid literal for int() with base 10: '{{ article.pk }}'
[2018-05-29 08:55:30,735][Thread-25:4484][task_id:django.request][exception.py:135][ERROR][Internal Server Error: /blog/up_down/]
Traceback (most recent call last):
  File "C:\Python36\lib\site-packages\django\core\handlers\exception.py", line 41, in inner
    response = get_response(request)
  File "C:\Python36\lib\site-packages\django\core\handlers\base.py", line 187, in _get_response
    response = self.process_exception_by_middleware(e, request)
  File "C:\Python36\lib\site-packages\django\core\handlers\base.py", line 185, in _get_response
    response = wrapped_callback(request, *callback_args, **callback_kwargs)
  File "D:\python10\day78\bbs\blog\views.py", line 347, in up_down
    is_up=json.loads(request.POST.get('is_up'))
  File "C:\Python36\lib\json\__init__.py", line 348, in loads
    'not {!r}'.format(s.__class__.__name__))
TypeError: the JSON object must be str, bytes or bytearray, not 'NoneType'
[2018-05-29 08:58:31,421][Thread-43:6968][task_id:requests.packages.urllib3.connectionpool][connectionpool.py:214][INFO][Starting new HTTP connection (1): api.geetest.com]
[2018-05-29 08:58:34,173][Thread-46:6168][task_id:requests.packages.urllib3.connectionpool][connectionpool.py:214][INFO][Starting new HTTP connection (1): api.geetest.com]
[2018-05-29 09:04:03,453][Thread-88:2884][task_id:requests.packages.urllib3.connectionpool][connectionpool.py:214][INFO][Starting new HTTP connection (1): api.geetest.com]
[2018-05-29 09:04:20,772][Thread-90:1648][task_id:requests.packages.urllib3.connectionpool][connectionpool.py:214][INFO][Starting new HTTP connection (1): api.geetest.com]
[2018-05-29 09:04:38,775][Thread-91:6972][task_id:requests.packages.urllib3.connectionpool][connectionpool.py:214][INFO][Starting new HTTP connection (1): api.geetest.com]
[2018-05-29 09:12:48,949][Thread-7:1568][task_id:django.security.csrf][csrf.py:160][WARNING][Forbidden (CSRF token missing or incorrect.): /blog/comment/]
[2018-05-29 10:20:23,240][Thread-61:6536][task_id:requests.packages.urllib3.connectionpool][connectionpool.py:214][INFO][Starting new HTTP connection (1): api.geetest.com]
[2018-05-29 10:20:36,804][Thread-63:5328][task_id:requests.packages.urllib3.connectionpool][connectionpool.py:214][INFO][Starting new HTTP connection (1): api.geetest.com]
[2018-05-29 10:21:36,228][Thread-94:5800][task_id:requests.packages.urllib3.connectionpool][connectionpool.py:214][INFO][Starting new HTTP connection (1): api.geetest.com]
[2018-05-29 10:21:45,728][Thread-95:5328][task_id:requests.packages.urllib3.connectionpool][connectionpool.py:214][INFO][Starting new HTTP connection (1): api.geetest.com]
[2018-05-29 10:33:24,161][Thread-166:7024][task_id:django.request][exception.py:135][ERROR][Internal Server Error: /blog/comment/]
Traceback (most recent call last):
  File "C:\Python36\lib\site-packages\django\core\handlers\exception.py", line 41, in inner
    response = get_response(request)
  File "C:\Python36\lib\site-packages\django\core\handlers\base.py", line 187, in _get_response
    response = self.process_exception_by_middleware(e, request)
  File "C:\Python36\lib\site-packages\django\core\handlers\base.py", line 185, in _get_response
    response = wrapped_callback(request, *callback_args, **callback_kwargs)
  File "D:\python10\day78\bbs\blog\views.py", line 394, in comment
    response["create_time"]=comment_obj.create_time
UnboundLocalError: local variable 'comment_obj' referenced before assignment
[2018-05-29 10:33:25,360][Thread-167:5708][task_id:django.request][exception.py:135][ERROR][Internal Server Error: /blog/comment/]
Traceback (most recent call last):
  File "C:\Python36\lib\site-packages\django\core\handlers\exception.py", line 41, in inner
    response = get_response(request)
  File "C:\Python36\lib\site-packages\django\core\handlers\base.py", line 187, in _get_response
    response = self.process_exception_by_middleware(e, request)
  File "C:\Python36\lib\site-packages\django\core\handlers\base.py", line 185, in _get_response
    response = wrapped_callback(request, *callback_args, **callback_kwargs)
  File "D:\python10\day78\bbs\blog\views.py", line 394, in comment
    response["create_time"]=comment_obj.create_time
UnboundLocalError: local variable 'comment_obj' referenced before assignment
[2018-05-29 10:33:40,798][Thread-172:1684][task_id:django.request][exception.py:135][ERROR][Internal Server Error: /blog/comment/]
Traceback (most recent call last):
  File "C:\Python36\lib\site-packages\django\db\backends\utils.py", line 65, in execute
    return self.cursor.execute(sql, params)
  File "C:\Python36\lib\site-packages\django\db\backends\mysql\base.py", line 101, in execute
    return self.cursor.execute(query, args)
  File "C:\Python36\lib\site-packages\pymysql\cursors.py", line 165, in execute
    result = self._query(query)
  File "C:\Python36\lib\site-packages\pymysql\cursors.py", line 321, in _query
    conn.query(q)
  File "C:\Python36\lib\site-packages\pymysql\connections.py", line 860, in query
    self._affected_rows = self._read_query_result(unbuffered=unbuffered)
  File "C:\Python36\lib\site-packages\pymysql\connections.py", line 1061, in _read_query_result
    result.read()
  File "C:\Python36\lib\site-packages\pymysql\connections.py", line 1349, in read
    first_packet = self.connection._read_packet()
  File "C:\Python36\lib\site-packages\pymysql\connections.py", line 1018, in _read_packet
    packet.check_error()
  File "C:\Python36\lib\site-packages\pymysql\connections.py", line 384, in check_error
    err.raise_mysql_exception(self._data)
  File "C:\Python36\lib\site-packages\pymysql\err.py", line 107, in raise_mysql_exception
    raise errorclass(errno, errval)
pymysql.err.IntegrityError: (1048, "Column 'article_id' cannot be null")

The above exception was the direct cause of the following exception:

Traceback (most recent call last):
  File "C:\Python36\lib\site-packages\django\core\handlers\exception.py", line 41, in inner
    response = get_response(request)
  File "C:\Python36\lib\site-packages\django\core\handlers\base.py", line 187, in _get_response
    response = self.process_exception_by_middleware(e, request)
  File "C:\Python36\lib\site-packages\django\core\handlers\base.py", line 185, in _get_response
    response = wrapped_callback(request, *callback_args, **callback_kwargs)
  File "D:\python10\day78\bbs\blog\views.py", line 391, in comment
    comment_obj=models.Comment.objects.create(article_id=article_id,user_id=user_pk,content=content)
  File "C:\Python36\lib\site-packages\django\db\models\manager.py", line 85, in manager_method
    return getattr(self.get_queryset(), name)(*args, **kwargs)
  File "C:\Python36\lib\site-packages\django\db\models\query.py", line 394, in create
    obj.save(force_insert=True, using=self.db)
  File "C:\Python36\lib\site-packages\django\db\models\base.py", line 808, in save
    force_update=force_update, update_fields=update_fields)
  File "C:\Python36\lib\site-packages\django\db\models\base.py", line 838, in save_base
    updated = self._save_table(raw, cls, force_insert, force_update, using, update_fields)
  File "C:\Python36\lib\site-packages\django\db\models\base.py", line 924, in _save_table
    result = self._do_insert(cls._base_manager, using, fields, update_pk, raw)
  File "C:\Python36\lib\site-packages\django\db\models\base.py", line 963, in _do_insert
    using=using, raw=raw)
  File "C:\Python36\lib\site-packages\django\db\models\manager.py", line 85, in manager_method
    return getattr(self.get_queryset(), name)(*args, **kwargs)
  File "C:\Python36\lib\site-packages\django\db\models\query.py", line 1076, in _insert
    return query.get_compiler(using=using).execute_sql(return_id)
  File "C:\Python36\lib\site-packages\django\db\models\sql\compiler.py", line 1107, in execute_sql
    cursor.execute(sql, params)
  File "C:\Python36\lib\site-packages\django\db\backends\utils.py", line 80, in execute
    return super(CursorDebugWrapper, self).execute(sql, params)
  File "C:\Python36\lib\site-packages\django\db\backends\utils.py", line 65, in execute
    return self.cursor.execute(sql, params)
  File "C:\Python36\lib\site-packages\django\db\utils.py", line 94, in __exit__
    six.reraise(dj_exc_type, dj_exc_value, traceback)
  File "C:\Python36\lib\site-packages\django\utils\six.py", line 685, in reraise
    raise value.with_traceback(tb)
  File "C:\Python36\lib\site-packages\django\db\backends\utils.py", line 65, in execute
    return self.cursor.execute(sql, params)
  File "C:\Python36\lib\site-packages\django\db\backends\mysql\base.py", line 101, in execute
    return self.cursor.execute(query, args)
  File "C:\Python36\lib\site-packages\pymysql\cursors.py", line 165, in execute
    result = self._query(query)
  File "C:\Python36\lib\site-packages\pymysql\cursors.py", line 321, in _query
    conn.query(q)
  File "C:\Python36\lib\site-packages\pymysql\connections.py", line 860, in query
    self._affected_rows = self._read_query_result(unbuffered=unbuffered)
  File "C:\Python36\lib\site-packages\pymysql\connections.py", line 1061, in _read_query_result
    result.read()
  File "C:\Python36\lib\site-packages\pymysql\connections.py", line 1349, in read
    first_packet = self.connection._read_packet()
  File "C:\Python36\lib\site-packages\pymysql\connections.py", line 1018, in _read_packet
    packet.check_error()
  File "C:\Python36\lib\site-packages\pymysql\connections.py", line 384, in check_error
    err.raise_mysql_exception(self._data)
  File "C:\Python36\lib\site-packages\pymysql\err.py", line 107, in raise_mysql_exception
    raise errorclass(errno, errval)
django.db.utils.IntegrityError: (1048, "Column 'article_id' cannot be null")
[2018-05-29 10:35:59,178][Thread-203:4820][task_id:django.request][exception.py:135][ERROR][Internal Server Error: /blog/comment/]
Traceback (most recent call last):
  File "C:\Python36\lib\site-packages\django\core\handlers\exception.py", line 41, in inner
    response = get_response(request)
  File "C:\Python36\lib\site-packages\django\core\handlers\base.py", line 187, in _get_response
    response = self.process_exception_by_middleware(e, request)
  File "C:\Python36\lib\site-packages\django\core\handlers\base.py", line 185, in _get_response
    response = wrapped_callback(request, *callback_args, **callback_kwargs)
  File "D:\python10\day78\bbs\blog\views.py", line 394, in comment
    response["create_time"]=comment_obj.create_time
UnboundLocalError: local variable 'comment_obj' referenced before assignment
[2018-05-29 10:41:31,647][Thread-26:2916][task_id:django.request][exception.py:135][ERROR][Internal Server Error: /blog/comment/]
Traceback (most recent call last):
  File "C:\Python36\lib\site-packages\django\core\handlers\exception.py", line 41, in inner
    response = get_response(request)
  File "C:\Python36\lib\site-packages\django\core\handlers\base.py", line 187, in _get_response
    response = self.process_exception_by_middleware(e, request)
  File "C:\Python36\lib\site-packages\django\core\handlers\base.py", line 185, in _get_response
    response = wrapped_callback(request, *callback_args, **callback_kwargs)
  File "D:\python10\day78\bbs\blog\views.py", line 394, in comment
    response["create_time"]=comment_obj.create_time.strftime("%Y-%m-%d")
UnboundLocalError: local variable 'comment_obj' referenced before assignment
[2018-05-29 11:31:08,523][Thread-15:4084][task_id:django.request][exception.py:135][ERROR][Internal Server Error: /blog/comment_tree/3]
Traceback (most recent call last):
  File "C:\Python36\lib\site-packages\django\core\handlers\exception.py", line 41, in inner
    response = get_response(request)
  File "C:\Python36\lib\site-packages\django\core\handlers\base.py", line 187, in _get_response
    response = self.process_exception_by_middleware(e, request)
  File "C:\Python36\lib\site-packages\django\core\handlers\base.py", line 185, in _get_response
    response = wrapped_callback(request, *callback_args, **callback_kwargs)
  File "D:\python10\day78\bbs\blog\views.py", line 410, in comment_tree
    return JsonResponse("")
TypeError: __init__() missing 1 required positional argument: 'data'
[2018-05-29 11:31:25,942][Thread-14:6496][task_id:blog.views][views.py:249][WARNING][又有人访问不存在页面了...]
[2018-05-29 11:32:05,213][Thread-26:5124][task_id:django.request][exception.py:135][ERROR][Internal Server Error: /blog/comment_tree/3/]
Traceback (most recent call last):
  File "C:\Python36\lib\site-packages\django\core\handlers\exception.py", line 41, in inner
    response = get_response(request)
  File "C:\Python36\lib\site-packages\django\core\handlers\base.py", line 187, in _get_response
    response = self.process_exception_by_middleware(e, request)
  File "C:\Python36\lib\site-packages\django\core\handlers\base.py", line 185, in _get_response
    response = wrapped_callback(request, *callback_args, **callback_kwargs)
  File "D:\python10\day78\bbs\blog\views.py", line 410, in comment_tree
    return JsonResponse("")
  File "C:\Python36\lib\site-packages\django\http\response.py", line 524, in __init__
    'In order to allow non-dict objects to be serialized set the '
TypeError: In order to allow non-dict objects to be serialized set the safe parameter to False.
[2022-03-14 14:51:00,364][MainThread:13860][task_id:django.utils.autoreload][autoreload.py:637][INFO][Watching for file changes with StatReloader]
[2022-03-14 14:52:09,637][MainThread:13860][task_id:django.utils.autoreload][autoreload.py:251][INFO][C:\Users\mi\Desktop\blog_one\blog\models.py changed, reloading.]
[2022-03-14 14:52:10,937][MainThread:10388][task_id:django.utils.autoreload][autoreload.py:637][INFO][Watching for file changes with StatReloader]
[2022-03-14 14:52:22,471][MainThread:6424][task_id:django.utils.autoreload][autoreload.py:637][INFO][Watching for file changes with StatReloader]
[2022-03-14 14:53:50,443][MainThread:6424][task_id:django.utils.autoreload][autoreload.py:251][INFO][C:\Users\mi\Desktop\blog_one\blog\models.py changed, reloading.]
[2022-03-14 14:53:51,737][MainThread:3368][task_id:django.utils.autoreload][autoreload.py:637][INFO][Watching for file changes with StatReloader]
[2022-03-14 14:53:56,511][MainThread:2496][task_id:django.utils.autoreload][autoreload.py:637][INFO][Watching for file changes with StatReloader]
[2022-03-14 14:54:21,161][MainThread:14516][task_id:django.utils.autoreload][autoreload.py:637][INFO][Watching for file changes with StatReloader]
[2022-03-14 14:54:44,994][MainThread:13064][task_id:django.utils.autoreload][autoreload.py:637][INFO][Watching for file changes with StatReloader]
[2022-03-14 14:55:54,264][MainThread:3644][task_id:django.utils.autoreload][autoreload.py:637][INFO][Watching for file changes with StatReloader]
[2022-03-14 14:55:57,380][Thread-1:2088][task_id:django.request][log.py:224][WARNING][Not Found: /media/avatars/tt.jpg]
[2022-03-14 14:55:57,383][Thread-6:6868][task_id:django.request][log.py:224][WARNING][Not Found: /media/avatars/111_gplr878.jpg]
[2022-03-14 14:55:57,682][Thread-6:6868][task_id:django.request][log.py:224][WARNING][Not Found: /favicon.ico]
[2022-03-14 14:56:00,897][Thread-1:2088][task_id:django.request][log.py:224][WARNING][Not Found: /media/avatars/tt.jpg]
[2022-03-14 14:56:00,898][Thread-6:6868][task_id:django.request][log.py:224][WARNING][Not Found: /media/avatars/111_gplr878.jpg]
[2022-03-14 14:59:27,813][MainThread:15724][task_id:django.utils.autoreload][autoreload.py:637][INFO][Watching for file changes with StatReloader]
[2022-03-14 15:01:56,988][MainThread:15724][task_id:django.utils.autoreload][autoreload.py:251][INFO][C:\Users\mi\Desktop\blog_one\bbs\settings.py changed, reloading.]
[2022-03-14 15:01:58,304][MainThread:5444][task_id:django.utils.autoreload][autoreload.py:637][INFO][Watching for file changes with StatReloader]
[2022-03-14 15:02:11,418][MainThread:5444][task_id:django.utils.autoreload][autoreload.py:251][INFO][C:\Users\mi\Desktop\blog_one\bbs\settings.py changed, reloading.]
[2022-03-14 15:05:01,410][MainThread:10112][task_id:django.utils.autoreload][autoreload.py:637][INFO][Watching for file changes with StatReloader]
[2022-03-14 15:05:43,364][Thread-1:7436][task_id:django.request][log.py:224][WARNING][Not Found: /favicon.ico]
[2022-03-14 15:12:13,331][Thread-2:12432][task_id:django.request][log.py:224][WARNING][Not Found: /inde]
[2022-03-14 15:12:18,221][Thread-2:12432][task_id:django.request][log.py:224][WARNING][Not Found: /media/]
[2022-03-14 15:12:20,676][Thread-2:12432][task_id:django.request][log.py:224][WARNING][Not Found: /media/]
[2022-03-14 15:12:22,149][Thread-2:12432][task_id:django.request][log.py:224][WARNING][Not Found: /media/]
[2022-03-14 15:12:45,765][Thread-2:12432][task_id:django.request][log.py:224][ERROR][Internal Server Error: /blog/qiqi/]
Traceback (most recent call last):
  File "E:\Software\Code\Py_environment\lib\site-packages\django\db\backends\utils.py", line 84, in _execute
    return self.cursor.execute(sql, params)
  File "E:\Software\Code\Py_environment\lib\site-packages\django\db\backends\sqlite3\base.py", line 423, in execute
    return Database.Cursor.execute(self, query, params)
sqlite3.OperationalError: no such function: date_format

The above exception was the direct cause of the following exception:

Traceback (most recent call last):
  File "E:\Software\Code\Py_environment\lib\site-packages\django\core\handlers\exception.py", line 47, in inner
    response = get_response(request)
  File "E:\Software\Code\Py_environment\lib\site-packages\django\core\handlers\base.py", line 181, in _get_response
    response = wrapped_callback(request, *callback_args, **callback_kwargs)
  File "C:\Users\mi\Desktop\blog_one\blog\views.py", line 293, in home
    return render(request, "home.html", {
  File "E:\Software\Code\Py_environment\lib\site-packages\django\shortcuts.py", line 19, in render
    content = loader.render_to_string(template_name, context, request, using=using)
  File "E:\Software\Code\Py_environment\lib\site-packages\django\template\loader.py", line 62, in render_to_string
    return template.render(context, request)
  File "E:\Software\Code\Py_environment\lib\site-packages\django\template\backends\django.py", line 61, in render
    return self.template.render(context)
  File "E:\Software\Code\Py_environment\lib\site-packages\django\template\base.py", line 170, in render
    return self._render(context)
  File "E:\Software\Code\Py_environment\lib\site-packages\django\template\base.py", line 162, in _render
    return self.nodelist.render(context)
  File "E:\Software\Code\Py_environment\lib\site-packages\django\template\base.py", line 938, in render
    bit = node.render_annotated(context)
  File "E:\Software\Code\Py_environment\lib\site-packages\django\template\base.py", line 905, in render_annotated
    return self.render(context)
  File "E:\Software\Code\Py_environment\lib\site-packages\django\template\loader_tags.py", line 150, in render
    return compiled_parent._render(context)
  File "E:\Software\Code\Py_environment\lib\site-packages\django\template\base.py", line 162, in _render
    return self.nodelist.render(context)
  File "E:\Software\Code\Py_environment\lib\site-packages\django\template\base.py", line 938, in render
    bit = node.render_annotated(context)
  File "E:\Software\Code\Py_environment\lib\site-packages\django\template\base.py", line 905, in render_annotated
    return self.render(context)
  File "E:\Software\Code\Py_environment\lib\site-packages\django\template\library.py", line 234, in render
    return t.render(new_context)
  File "E:\Software\Code\Py_environment\lib\site-packages\django\template\base.py", line 172, in render
    return self._render(context)
  File "E:\Software\Code\Py_environment\lib\site-packages\django\template\base.py", line 162, in _render
    return self.nodelist.render(context)
  File "E:\Software\Code\Py_environment\lib\site-packages\django\template\base.py", line 938, in render
    bit = node.render_annotated(context)
  File "E:\Software\Code\Py_environment\lib\site-packages\django\template\base.py", line 905, in render_annotated
    return self.render(context)
  File "E:\Software\Code\Py_environment\lib\site-packages\django\template\defaulttags.py", line 168, in render
    len_values = len(values)
  File "E:\Software\Code\Py_environment\lib\site-packages\django\db\models\query.py", line 262, in __len__
    self._fetch_all()
  File "E:\Software\Code\Py_environment\lib\site-packages\django\db\models\query.py", line 1324, in _fetch_all
    self._result_cache = list(self._iterable_class(self))
  File "E:\Software\Code\Py_environment\lib\site-packages\django\db\models\query.py", line 109, in __iter__
    for row in compiler.results_iter(chunked_fetch=self.chunked_fetch, chunk_size=self.chunk_size):
  File "E:\Software\Code\Py_environment\lib\site-packages\django\db\models\sql\compiler.py", line 1130, in results_iter
    results = self.execute_sql(MULTI, chunked_fetch=chunked_fetch, chunk_size=chunk_size)
  File "E:\Software\Code\Py_environment\lib\site-packages\django\db\models\sql\compiler.py", line 1175, in execute_sql
    cursor.execute(sql, params)
  File "E:\Software\Code\Py_environment\lib\site-packages\django\db\backends\utils.py", line 98, in execute
    return super().execute(sql, params)
  File "E:\Software\Code\Py_environment\lib\site-packages\django\db\backends\utils.py", line 66, in execute
    return self._execute_with_wrappers(sql, params, many=False, executor=self._execute)
  File "E:\Software\Code\Py_environment\lib\site-packages\django\db\backends\utils.py", line 75, in _execute_with_wrappers
    return executor(sql, params, many, context)
  File "E:\Software\Code\Py_environment\lib\site-packages\django\db\backends\utils.py", line 84, in _execute
    return self.cursor.execute(sql, params)
  File "E:\Software\Code\Py_environment\lib\site-packages\django\db\utils.py", line 90, in __exit__
    raise dj_exc_value.with_traceback(traceback) from exc_value
  File "E:\Software\Code\Py_environment\lib\site-packages\django\db\backends\utils.py", line 84, in _execute
    return self.cursor.execute(sql, params)
  File "E:\Software\Code\Py_environment\lib\site-packages\django\db\backends\sqlite3\base.py", line 423, in execute
    return Database.Cursor.execute(self, query, params)
django.db.utils.OperationalError: no such function: date_format
[2022-03-14 15:13:49,041][MainThread:10112][task_id:django.utils.autoreload][autoreload.py:251][INFO][C:\Users\mi\Desktop\blog_one\bbs\settings.py changed, reloading.]
[2022-03-14 15:13:50,408][MainThread:832][task_id:django.utils.autoreload][autoreload.py:637][INFO][Watching for file changes with StatReloader]
[2022-03-14 15:13:50,906][Thread-1:14536][task_id:django.request][log.py:224][ERROR][Internal Server Error: /blog/qiqi/]
Traceback (most recent call last):
  File "E:\Software\Code\Py_environment\lib\site-packages\django\db\backends\utils.py", line 84, in _execute
    return self.cursor.execute(sql, params)
  File "E:\Software\Code\Py_environment\lib\site-packages\django\db\backends\sqlite3\base.py", line 423, in execute
    return Database.Cursor.execute(self, query, params)
sqlite3.OperationalError: no such function: date_format

The above exception was the direct cause of the following exception:

Traceback (most recent call last):
  File "E:\Software\Code\Py_environment\lib\site-packages\django\core\handlers\exception.py", line 47, in inner
    response = get_response(request)
  File "E:\Software\Code\Py_environment\lib\site-packages\django\core\handlers\base.py", line 181, in _get_response
    response = wrapped_callback(request, *callback_args, **callback_kwargs)
  File "C:\Users\mi\Desktop\blog_one\blog\views.py", line 293, in home
    return render(request, "home.html", {
  File "E:\Software\Code\Py_environment\lib\site-packages\django\shortcuts.py", line 19, in render
    content = loader.render_to_string(template_name, context, request, using=using)
  File "E:\Software\Code\Py_environment\lib\site-packages\django\template\loader.py", line 62, in render_to_string
    return template.render(context, request)
  File "E:\Software\Code\Py_environment\lib\site-packages\django\template\backends\django.py", line 61, in render
    return self.template.render(context)
  File "E:\Software\Code\Py_environment\lib\site-packages\django\template\base.py", line 170, in render
    return self._render(context)
  File "E:\Software\Code\Py_environment\lib\site-packages\django\template\base.py", line 162, in _render
    return self.nodelist.render(context)
  File "E:\Software\Code\Py_environment\lib\site-packages\django\template\base.py", line 938, in render
    bit = node.render_annotated(context)
  File "E:\Software\Code\Py_environment\lib\site-packages\django\template\base.py", line 905, in render_annotated
    return self.render(context)
  File "E:\Software\Code\Py_environment\lib\site-packages\django\template\loader_tags.py", line 150, in render
    return compiled_parent._render(context)
  File "E:\Software\Code\Py_environment\lib\site-packages\django\template\base.py", line 162, in _render
    return self.nodelist.render(context)
  File "E:\Software\Code\Py_environment\lib\site-packages\django\template\base.py", line 938, in render
    bit = node.render_annotated(context)
  File "E:\Software\Code\Py_environment\lib\site-packages\django\template\base.py", line 905, in render_annotated
    return self.render(context)
  File "E:\Software\Code\Py_environment\lib\site-packages\django\template\library.py", line 234, in render
    return t.render(new_context)
  File "E:\Software\Code\Py_environment\lib\site-packages\django\template\base.py", line 172, in render
    return self._render(context)
  File "E:\Software\Code\Py_environment\lib\site-packages\django\template\base.py", line 162, in _render
    return self.nodelist.render(context)
  File "E:\Software\Code\Py_environment\lib\site-packages\django\template\base.py", line 938, in render
    bit = node.render_annotated(context)
  File "E:\Software\Code\Py_environment\lib\site-packages\django\template\base.py", line 905, in render_annotated
    return self.render(context)
  File "E:\Software\Code\Py_environment\lib\site-packages\django\template\defaulttags.py", line 168, in render
    len_values = len(values)
  File "E:\Software\Code\Py_environment\lib\site-packages\django\db\models\query.py", line 262, in __len__
    self._fetch_all()
  File "E:\Software\Code\Py_environment\lib\site-packages\django\db\models\query.py", line 1324, in _fetch_all
    self._result_cache = list(self._iterable_class(self))
  File "E:\Software\Code\Py_environment\lib\site-packages\django\db\models\query.py", line 109, in __iter__
    for row in compiler.results_iter(chunked_fetch=self.chunked_fetch, chunk_size=self.chunk_size):
  File "E:\Software\Code\Py_environment\lib\site-packages\django\db\models\sql\compiler.py", line 1130, in results_iter
    results = self.execute_sql(MULTI, chunked_fetch=chunked_fetch, chunk_size=chunk_size)
  File "E:\Software\Code\Py_environment\lib\site-packages\django\db\models\sql\compiler.py", line 1175, in execute_sql
    cursor.execute(sql, params)
  File "E:\Software\Code\Py_environment\lib\site-packages\django\db\backends\utils.py", line 98, in execute
    return super().execute(sql, params)
  File "E:\Software\Code\Py_environment\lib\site-packages\django\db\backends\utils.py", line 66, in execute
    return self._execute_with_wrappers(sql, params, many=False, executor=self._execute)
  File "E:\Software\Code\Py_environment\lib\site-packages\django\db\backends\utils.py", line 75, in _execute_with_wrappers
    return executor(sql, params, many, context)
  File "E:\Software\Code\Py_environment\lib\site-packages\django\db\backends\utils.py", line 84, in _execute
    return self.cursor.execute(sql, params)
  File "E:\Software\Code\Py_environment\lib\site-packages\django\db\utils.py", line 90, in __exit__
    raise dj_exc_value.with_traceback(traceback) from exc_value
  File "E:\Software\Code\Py_environment\lib\site-packages\django\db\backends\utils.py", line 84, in _execute
    return self.cursor.execute(sql, params)
  File "E:\Software\Code\Py_environment\lib\site-packages\django\db\backends\sqlite3\base.py", line 423, in execute
    return Database.Cursor.execute(self, query, params)
django.db.utils.OperationalError: no such function: date_format
[2022-03-14 15:13:53,067][Thread-1:14536][task_id:django.request][log.py:224][WARNING][Not Found: /media/]
[2022-03-14 15:13:55,870][Thread-1:14536][task_id:django.request][log.py:224][ERROR][Internal Server Error: /blog/qiqi/]
Traceback (most recent call last):
  File "E:\Software\Code\Py_environment\lib\site-packages\django\db\backends\utils.py", line 84, in _execute
    return self.cursor.execute(sql, params)
  File "E:\Software\Code\Py_environment\lib\site-packages\django\db\backends\sqlite3\base.py", line 423, in execute
    return Database.Cursor.execute(self, query, params)
sqlite3.OperationalError: no such function: date_format

The above exception was the direct cause of the following exception:

Traceback (most recent call last):
  File "E:\Software\Code\Py_environment\lib\site-packages\django\core\handlers\exception.py", line 47, in inner
    response = get_response(request)
  File "E:\Software\Code\Py_environment\lib\site-packages\django\core\handlers\base.py", line 181, in _get_response
    response = wrapped_callback(request, *callback_args, **callback_kwargs)
  File "C:\Users\mi\Desktop\blog_one\blog\views.py", line 293, in home
    return render(request, "home.html", {
  File "E:\Software\Code\Py_environment\lib\site-packages\django\shortcuts.py", line 19, in render
    content = loader.render_to_string(template_name, context, request, using=using)
  File "E:\Software\Code\Py_environment\lib\site-packages\django\template\loader.py", line 62, in render_to_string
    return template.render(context, request)
  File "E:\Software\Code\Py_environment\lib\site-packages\django\template\backends\django.py", line 61, in render
    return self.template.render(context)
  File "E:\Software\Code\Py_environment\lib\site-packages\django\template\base.py", line 170, in render
    return self._render(context)
  File "E:\Software\Code\Py_environment\lib\site-packages\django\template\base.py", line 162, in _render
    return self.nodelist.render(context)
  File "E:\Software\Code\Py_environment\lib\site-packages\django\template\base.py", line 938, in render
    bit = node.render_annotated(context)
  File "E:\Software\Code\Py_environment\lib\site-packages\django\template\base.py", line 905, in render_annotated
    return self.render(context)
  File "E:\Software\Code\Py_environment\lib\site-packages\django\template\loader_tags.py", line 150, in render
    return compiled_parent._render(context)
  File "E:\Software\Code\Py_environment\lib\site-packages\django\template\base.py", line 162, in _render
    return self.nodelist.render(context)
  File "E:\Software\Code\Py_environment\lib\site-packages\django\template\base.py", line 938, in render
    bit = node.render_annotated(context)
  File "E:\Software\Code\Py_environment\lib\site-packages\django\template\base.py", line 905, in render_annotated
    return self.render(context)
  File "E:\Software\Code\Py_environment\lib\site-packages\django\template\library.py", line 234, in render
    return t.render(new_context)
  File "E:\Software\Code\Py_environment\lib\site-packages\django\template\base.py", line 172, in render
    return self._render(context)
  File "E:\Software\Code\Py_environment\lib\site-packages\django\template\base.py", line 162, in _render
    return self.nodelist.render(context)
  File "E:\Software\Code\Py_environment\lib\site-packages\django\template\base.py", line 938, in render
    bit = node.render_annotated(context)
  File "E:\Software\Code\Py_environment\lib\site-packages\django\template\base.py", line 905, in render_annotated
    return self.render(context)
  File "E:\Software\Code\Py_environment\lib\site-packages\django\template\defaulttags.py", line 168, in render
    len_values = len(values)
  File "E:\Software\Code\Py_environment\lib\site-packages\django\db\models\query.py", line 262, in __len__
    self._fetch_all()
  File "E:\Software\Code\Py_environment\lib\site-packages\django\db\models\query.py", line 1324, in _fetch_all
    self._result_cache = list(self._iterable_class(self))
  File "E:\Software\Code\Py_environment\lib\site-packages\django\db\models\query.py", line 109, in __iter__
    for row in compiler.results_iter(chunked_fetch=self.chunked_fetch, chunk_size=self.chunk_size):
  File "E:\Software\Code\Py_environment\lib\site-packages\django\db\models\sql\compiler.py", line 1130, in results_iter
    results = self.execute_sql(MULTI, chunked_fetch=chunked_fetch, chunk_size=chunk_size)
  File "E:\Software\Code\Py_environment\lib\site-packages\django\db\models\sql\compiler.py", line 1175, in execute_sql
    cursor.execute(sql, params)
  File "E:\Software\Code\Py_environment\lib\site-packages\django\db\backends\utils.py", line 98, in execute
    return super().execute(sql, params)
  File "E:\Software\Code\Py_environment\lib\site-packages\django\db\backends\utils.py", line 66, in execute
    return self._execute_with_wrappers(sql, params, many=False, executor=self._execute)
  File "E:\Software\Code\Py_environment\lib\site-packages\django\db\backends\utils.py", line 75, in _execute_with_wrappers
    return executor(sql, params, many, context)
  File "E:\Software\Code\Py_environment\lib\site-packages\django\db\backends\utils.py", line 84, in _execute
    return self.cursor.execute(sql, params)
  File "E:\Software\Code\Py_environment\lib\site-packages\django\db\utils.py", line 90, in __exit__
    raise dj_exc_value.with_traceback(traceback) from exc_value
  File "E:\Software\Code\Py_environment\lib\site-packages\django\db\backends\utils.py", line 84, in _execute
    return self.cursor.execute(sql, params)
  File "E:\Software\Code\Py_environment\lib\site-packages\django\db\backends\sqlite3\base.py", line 423, in execute
    return Database.Cursor.execute(self, query, params)
django.db.utils.OperationalError: no such function: date_format
[2022-03-14 15:14:01,135][Thread-1:14536][task_id:django.request][log.py:224][ERROR][Internal Server Error: /blog/qiqi/]
Traceback (most recent call last):
  File "E:\Software\Code\Py_environment\lib\site-packages\django\db\backends\utils.py", line 84, in _execute
    return self.cursor.execute(sql, params)
  File "E:\Software\Code\Py_environment\lib\site-packages\django\db\backends\sqlite3\base.py", line 423, in execute
    return Database.Cursor.execute(self, query, params)
sqlite3.OperationalError: no such function: date_format

The above exception was the direct cause of the following exception:

Traceback (most recent call last):
  File "E:\Software\Code\Py_environment\lib\site-packages\django\core\handlers\exception.py", line 47, in inner
    response = get_response(request)
  File "E:\Software\Code\Py_environment\lib\site-packages\django\core\handlers\base.py", line 181, in _get_response
    response = wrapped_callback(request, *callback_args, **callback_kwargs)
  File "C:\Users\mi\Desktop\blog_one\blog\views.py", line 293, in home
    return render(request, "home.html", {
  File "E:\Software\Code\Py_environment\lib\site-packages\django\shortcuts.py", line 19, in render
    content = loader.render_to_string(template_name, context, request, using=using)
  File "E:\Software\Code\Py_environment\lib\site-packages\django\template\loader.py", line 62, in render_to_string
    return template.render(context, request)
  File "E:\Software\Code\Py_environment\lib\site-packages\django\template\backends\django.py", line 61, in render
    return self.template.render(context)
  File "E:\Software\Code\Py_environment\lib\site-packages\django\template\base.py", line 170, in render
    return self._render(context)
  File "E:\Software\Code\Py_environment\lib\site-packages\django\template\base.py", line 162, in _render
    return self.nodelist.render(context)
  File "E:\Software\Code\Py_environment\lib\site-packages\django\template\base.py", line 938, in render
    bit = node.render_annotated(context)
  File "E:\Software\Code\Py_environment\lib\site-packages\django\template\base.py", line 905, in render_annotated
    return self.render(context)
  File "E:\Software\Code\Py_environment\lib\site-packages\django\template\loader_tags.py", line 150, in render
    return compiled_parent._render(context)
  File "E:\Software\Code\Py_environment\lib\site-packages\django\template\base.py", line 162, in _render
    return self.nodelist.render(context)
  File "E:\Software\Code\Py_environment\lib\site-packages\django\template\base.py", line 938, in render
    bit = node.render_annotated(context)
  File "E:\Software\Code\Py_environment\lib\site-packages\django\template\base.py", line 905, in render_annotated
    return self.render(context)
  File "E:\Software\Code\Py_environment\lib\site-packages\django\template\library.py", line 234, in render
    return t.render(new_context)
  File "E:\Software\Code\Py_environment\lib\site-packages\django\template\base.py", line 172, in render
    return self._render(context)
  File "E:\Software\Code\Py_environment\lib\site-packages\django\template\base.py", line 162, in _render
    return self.nodelist.render(context)
  File "E:\Software\Code\Py_environment\lib\site-packages\django\template\base.py", line 938, in render
    bit = node.render_annotated(context)
  File "E:\Software\Code\Py_environment\lib\site-packages\django\template\base.py", line 905, in render_annotated
    return self.render(context)
  File "E:\Software\Code\Py_environment\lib\site-packages\django\template\defaulttags.py", line 168, in render
    len_values = len(values)
  File "E:\Software\Code\Py_environment\lib\site-packages\django\db\models\query.py", line 262, in __len__
    self._fetch_all()
  File "E:\Software\Code\Py_environment\lib\site-packages\django\db\models\query.py", line 1324, in _fetch_all
    self._result_cache = list(self._iterable_class(self))
  File "E:\Software\Code\Py_environment\lib\site-packages\django\db\models\query.py", line 109, in __iter__
    for row in compiler.results_iter(chunked_fetch=self.chunked_fetch, chunk_size=self.chunk_size):
  File "E:\Software\Code\Py_environment\lib\site-packages\django\db\models\sql\compiler.py", line 1130, in results_iter
    results = self.execute_sql(MULTI, chunked_fetch=chunked_fetch, chunk_size=chunk_size)
  File "E:\Software\Code\Py_environment\lib\site-packages\django\db\models\sql\compiler.py", line 1175, in execute_sql
    cursor.execute(sql, params)
  File "E:\Software\Code\Py_environment\lib\site-packages\django\db\backends\utils.py", line 98, in execute
    return super().execute(sql, params)
  File "E:\Software\Code\Py_environment\lib\site-packages\django\db\backends\utils.py", line 66, in execute
    return self._execute_with_wrappers(sql, params, many=False, executor=self._execute)
  File "E:\Software\Code\Py_environment\lib\site-packages\django\db\backends\utils.py", line 75, in _execute_with_wrappers
    return executor(sql, params, many, context)
  File "E:\Software\Code\Py_environment\lib\site-packages\django\db\backends\utils.py", line 84, in _execute
    return self.cursor.execute(sql, params)
  File "E:\Software\Code\Py_environment\lib\site-packages\django\db\utils.py", line 90, in __exit__
    raise dj_exc_value.with_traceback(traceback) from exc_value
  File "E:\Software\Code\Py_environment\lib\site-packages\django\db\backends\utils.py", line 84, in _execute
    return self.cursor.execute(sql, params)
  File "E:\Software\Code\Py_environment\lib\site-packages\django\db\backends\sqlite3\base.py", line 423, in execute
    return Database.Cursor.execute(self, query, params)
django.db.utils.OperationalError: no such function: date_format
[2022-03-16 15:22:17,723][MainThread:17424][task_id:django.utils.autoreload][autoreload.py:637][INFO][Watching for file changes with StatReloader]
[2022-03-16 15:22:22,557][Thread-1:11044][task_id:django.request][log.py:224][WARNING][Not Found: /media/]
[2022-03-16 15:22:22,687][Thread-1:11044][task_id:django.request][log.py:224][WARNING][Not Found: /favicon.ico]
[2022-03-16 15:22:31,040][Thread-2:12024][task_id:django.request][log.py:224][WARNING][Not Found: /media/]
[2022-03-16 15:22:39,032][Thread-2:12024][task_id:django.request][log.py:224][WARNING][Not Found: /media/]
[2022-03-16 15:23:41,975][Thread-2:12024][task_id:django.request][log.py:224][WARNING][Not Found: /media/]
[2022-03-16 15:23:43,348][Thread-2:12024][task_id:django.request][log.py:224][ERROR][Internal Server Error: /blog/qiqi/]
Traceback (most recent call last):
  File "E:\Software\Code\Py_environment\lib\site-packages\django\db\backends\utils.py", line 84, in _execute
    return self.cursor.execute(sql, params)
  File "E:\Software\Code\Py_environment\lib\site-packages\django\db\backends\sqlite3\base.py", line 423, in execute
    return Database.Cursor.execute(self, query, params)
sqlite3.OperationalError: no such function: date_format

The above exception was the direct cause of the following exception:

Traceback (most recent call last):
  File "E:\Software\Code\Py_environment\lib\site-packages\django\core\handlers\exception.py", line 47, in inner
    response = get_response(request)
  File "E:\Software\Code\Py_environment\lib\site-packages\django\core\handlers\base.py", line 181, in _get_response
    response = wrapped_callback(request, *callback_args, **callback_kwargs)
  File "C:\Users\mi\Desktop\blog_one\blog\views.py", line 293, in home
    return render(request, "home.html", {
  File "E:\Software\Code\Py_environment\lib\site-packages\django\shortcuts.py", line 19, in render
    content = loader.render_to_string(template_name, context, request, using=using)
  File "E:\Software\Code\Py_environment\lib\site-packages\django\template\loader.py", line 62, in render_to_string
    return template.render(context, request)
  File "E:\Software\Code\Py_environment\lib\site-packages\django\template\backends\django.py", line 61, in render
    return self.template.render(context)
  File "E:\Software\Code\Py_environment\lib\site-packages\django\template\base.py", line 170, in render
    return self._render(context)
  File "E:\Software\Code\Py_environment\lib\site-packages\django\template\base.py", line 162, in _render
    return self.nodelist.render(context)
  File "E:\Software\Code\Py_environment\lib\site-packages\django\template\base.py", line 938, in render
    bit = node.render_annotated(context)
  File "E:\Software\Code\Py_environment\lib\site-packages\django\template\base.py", line 905, in render_annotated
    return self.render(context)
  File "E:\Software\Code\Py_environment\lib\site-packages\django\template\loader_tags.py", line 150, in render
    return compiled_parent._render(context)
  File "E:\Software\Code\Py_environment\lib\site-packages\django\template\base.py", line 162, in _render
    return self.nodelist.render(context)
  File "E:\Software\Code\Py_environment\lib\site-packages\django\template\base.py", line 938, in render
    bit = node.render_annotated(context)
  File "E:\Software\Code\Py_environment\lib\site-packages\django\template\base.py", line 905, in render_annotated
    return self.render(context)
  File "E:\Software\Code\Py_environment\lib\site-packages\django\template\library.py", line 234, in render
    return t.render(new_context)
  File "E:\Software\Code\Py_environment\lib\site-packages\django\template\base.py", line 172, in render
    return self._render(context)
  File "E:\Software\Code\Py_environment\lib\site-packages\django\template\base.py", line 162, in _render
    return self.nodelist.render(context)
  File "E:\Software\Code\Py_environment\lib\site-packages\django\template\base.py", line 938, in render
    bit = node.render_annotated(context)
  File "E:\Software\Code\Py_environment\lib\site-packages\django\template\base.py", line 905, in render_annotated
    return self.render(context)
  File "E:\Software\Code\Py_environment\lib\site-packages\django\template\defaulttags.py", line 168, in render
    len_values = len(values)
  File "E:\Software\Code\Py_environment\lib\site-packages\django\db\models\query.py", line 262, in __len__
    self._fetch_all()
  File "E:\Software\Code\Py_environment\lib\site-packages\django\db\models\query.py", line 1324, in _fetch_all
    self._result_cache = list(self._iterable_class(self))
  File "E:\Software\Code\Py_environment\lib\site-packages\django\db\models\query.py", line 109, in __iter__
    for row in compiler.results_iter(chunked_fetch=self.chunked_fetch, chunk_size=self.chunk_size):
  File "E:\Software\Code\Py_environment\lib\site-packages\django\db\models\sql\compiler.py", line 1130, in results_iter
    results = self.execute_sql(MULTI, chunked_fetch=chunked_fetch, chunk_size=chunk_size)
  File "E:\Software\Code\Py_environment\lib\site-packages\django\db\models\sql\compiler.py", line 1175, in execute_sql
    cursor.execute(sql, params)
  File "E:\Software\Code\Py_environment\lib\site-packages\django\db\backends\utils.py", line 98, in execute
    return super().execute(sql, params)
  File "E:\Software\Code\Py_environment\lib\site-packages\django\db\backends\utils.py", line 66, in execute
    return self._execute_with_wrappers(sql, params, many=False, executor=self._execute)
  File "E:\Software\Code\Py_environment\lib\site-packages\django\db\backends\utils.py", line 75, in _execute_with_wrappers
    return executor(sql, params, many, context)
  File "E:\Software\Code\Py_environment\lib\site-packages\django\db\backends\utils.py", line 84, in _execute
    return self.cursor.execute(sql, params)
  File "E:\Software\Code\Py_environment\lib\site-packages\django\db\utils.py", line 90, in __exit__
    raise dj_exc_value.with_traceback(traceback) from exc_value
  File "E:\Software\Code\Py_environment\lib\site-packages\django\db\backends\utils.py", line 84, in _execute
    return self.cursor.execute(sql, params)
  File "E:\Software\Code\Py_environment\lib\site-packages\django\db\backends\sqlite3\base.py", line 423, in execute
    return Database.Cursor.execute(self, query, params)
django.db.utils.OperationalError: no such function: date_format
[2022-03-16 15:24:07,261][MainThread:6460][task_id:django.utils.autoreload][autoreload.py:637][INFO][Watching for file changes with StatReloader]
[2022-03-16 15:24:09,448][Thread-1:10764][task_id:django.request][log.py:224][WARNING][Not Found: /media/]
[2022-03-16 15:24:14,949][Thread-1:10764][task_id:django.request][log.py:224][ERROR][Internal Server Error: /blog/qiqi/]
Traceback (most recent call last):
  File "E:\Software\Code\Py_environment\lib\site-packages\django\db\backends\utils.py", line 84, in _execute
    return self.cursor.execute(sql, params)
  File "E:\Software\Code\Py_environment\lib\site-packages\django\db\backends\sqlite3\base.py", line 423, in execute
    return Database.Cursor.execute(self, query, params)
sqlite3.OperationalError: no such function: date_format

The above exception was the direct cause of the following exception:

Traceback (most recent call last):
  File "E:\Software\Code\Py_environment\lib\site-packages\django\core\handlers\exception.py", line 47, in inner
    response = get_response(request)
  File "E:\Software\Code\Py_environment\lib\site-packages\django\core\handlers\base.py", line 181, in _get_response
    response = wrapped_callback(request, *callback_args, **callback_kwargs)
  File "C:\Users\mi\Desktop\blog_one\blog\views.py", line 293, in home
    return render(request, "home.html", {
  File "E:\Software\Code\Py_environment\lib\site-packages\django\shortcuts.py", line 19, in render
    content = loader.render_to_string(template_name, context, request, using=using)
  File "E:\Software\Code\Py_environment\lib\site-packages\django\template\loader.py", line 62, in render_to_string
    return template.render(context, request)
  File "E:\Software\Code\Py_environment\lib\site-packages\django\template\backends\django.py", line 61, in render
    return self.template.render(context)
  File "E:\Software\Code\Py_environment\lib\site-packages\django\template\base.py", line 170, in render
    return self._render(context)
  File "E:\Software\Code\Py_environment\lib\site-packages\django\template\base.py", line 162, in _render
    return self.nodelist.render(context)
  File "E:\Software\Code\Py_environment\lib\site-packages\django\template\base.py", line 938, in render
    bit = node.render_annotated(context)
  File "E:\Software\Code\Py_environment\lib\site-packages\django\template\base.py", line 905, in render_annotated
    return self.render(context)
  File "E:\Software\Code\Py_environment\lib\site-packages\django\template\loader_tags.py", line 150, in render
    return compiled_parent._render(context)
  File "E:\Software\Code\Py_environment\lib\site-packages\django\template\base.py", line 162, in _render
    return self.nodelist.render(context)
  File "E:\Software\Code\Py_environment\lib\site-packages\django\template\base.py", line 938, in render
    bit = node.render_annotated(context)
  File "E:\Software\Code\Py_environment\lib\site-packages\django\template\base.py", line 905, in render_annotated
    return self.render(context)
  File "E:\Software\Code\Py_environment\lib\site-packages\django\template\library.py", line 234, in render
    return t.render(new_context)
  File "E:\Software\Code\Py_environment\lib\site-packages\django\template\base.py", line 172, in render
    return self._render(context)
  File "E:\Software\Code\Py_environment\lib\site-packages\django\template\base.py", line 162, in _render
    return self.nodelist.render(context)
  File "E:\Software\Code\Py_environment\lib\site-packages\django\template\base.py", line 938, in render
    bit = node.render_annotated(context)
  File "E:\Software\Code\Py_environment\lib\site-packages\django\template\base.py", line 905, in render_annotated
    return self.render(context)
  File "E:\Software\Code\Py_environment\lib\site-packages\django\template\defaulttags.py", line 168, in render
    len_values = len(values)
  File "E:\Software\Code\Py_environment\lib\site-packages\django\db\models\query.py", line 262, in __len__
    self._fetch_all()
  File "E:\Software\Code\Py_environment\lib\site-packages\django\db\models\query.py", line 1324, in _fetch_all
    self._result_cache = list(self._iterable_class(self))
  File "E:\Software\Code\Py_environment\lib\site-packages\django\db\models\query.py", line 109, in __iter__
    for row in compiler.results_iter(chunked_fetch=self.chunked_fetch, chunk_size=self.chunk_size):
  File "E:\Software\Code\Py_environment\lib\site-packages\django\db\models\sql\compiler.py", line 1130, in results_iter
    results = self.execute_sql(MULTI, chunked_fetch=chunked_fetch, chunk_size=chunk_size)
  File "E:\Software\Code\Py_environment\lib\site-packages\django\db\models\sql\compiler.py", line 1175, in execute_sql
    cursor.execute(sql, params)
  File "E:\Software\Code\Py_environment\lib\site-packages\django\db\backends\utils.py", line 98, in execute
    return super().execute(sql, params)
  File "E:\Software\Code\Py_environment\lib\site-packages\django\db\backends\utils.py", line 66, in execute
    return self._execute_with_wrappers(sql, params, many=False, executor=self._execute)
  File "E:\Software\Code\Py_environment\lib\site-packages\django\db\backends\utils.py", line 75, in _execute_with_wrappers
    return executor(sql, params, many, context)
  File "E:\Software\Code\Py_environment\lib\site-packages\django\db\backends\utils.py", line 84, in _execute
    return self.cursor.execute(sql, params)
  File "E:\Software\Code\Py_environment\lib\site-packages\django\db\utils.py", line 90, in __exit__
    raise dj_exc_value.with_traceback(traceback) from exc_value
  File "E:\Software\Code\Py_environment\lib\site-packages\django\db\backends\utils.py", line 84, in _execute
    return self.cursor.execute(sql, params)
  File "E:\Software\Code\Py_environment\lib\site-packages\django\db\backends\sqlite3\base.py", line 423, in execute
    return Database.Cursor.execute(self, query, params)
django.db.utils.OperationalError: no such function: date_format
[2022-03-16 15:25:11,850][Thread-1:10764][task_id:django.request][log.py:224][WARNING][Not Found: /media/]
[2022-03-16 15:25:20,321][Thread-1:10764][task_id:django.request][log.py:224][WARNING][Not Found: /media/]
[2022-03-16 15:25:21,901][Thread-1:10764][task_id:django.request][log.py:224][WARNING][Not Found: /media/]
[2022-03-16 15:25:23,779][Thread-1:10764][task_id:django.request][log.py:224][WARNING][Not Found: /media/]
[2022-03-16 15:27:34,799][MainThread:7420][task_id:django.utils.autoreload][autoreload.py:637][INFO][Watching for file changes with StatReloader]
[2022-03-16 15:27:47,816][Thread-1:13140][task_id:django.request][log.py:224][WARNING][Not Found: /media/]
[2022-03-16 15:27:49,237][Thread-1:13140][task_id:django.request][log.py:224][WARNING][Not Found: /media/]
[2022-03-16 15:27:51,173][Thread-1:13140][task_id:django.request][log.py:224][WARNING][Not Found: /media/]
[2022-03-16 15:27:51,769][Thread-1:13140][task_id:django.request][log.py:224][WARNING][Not Found: /media/]
[2022-03-16 15:27:56,583][Thread-1:13140][task_id:django.request][log.py:224][ERROR][Internal Server Error: /blog/qiqi/]
Traceback (most recent call last):
  File "E:\Software\Code\Py_environment\lib\site-packages\django\db\backends\utils.py", line 84, in _execute
    return self.cursor.execute(sql, params)
  File "E:\Software\Code\Py_environment\lib\site-packages\django\db\backends\sqlite3\base.py", line 423, in execute
    return Database.Cursor.execute(self, query, params)
sqlite3.OperationalError: no such function: date_format

The above exception was the direct cause of the following exception:

Traceback (most recent call last):
  File "E:\Software\Code\Py_environment\lib\site-packages\django\core\handlers\exception.py", line 47, in inner
    response = get_response(request)
  File "E:\Software\Code\Py_environment\lib\site-packages\django\core\handlers\base.py", line 181, in _get_response
    response = wrapped_callback(request, *callback_args, **callback_kwargs)
  File "C:\Users\mi\Desktop\blog_one\blog\views.py", line 293, in home
    return render(request, "home.html", {
  File "E:\Software\Code\Py_environment\lib\site-packages\django\shortcuts.py", line 19, in render
    content = loader.render_to_string(template_name, context, request, using=using)
  File "E:\Software\Code\Py_environment\lib\site-packages\django\template\loader.py", line 62, in render_to_string
    return template.render(context, request)
  File "E:\Software\Code\Py_environment\lib\site-packages\django\template\backends\django.py", line 61, in render
    return self.template.render(context)
  File "E:\Software\Code\Py_environment\lib\site-packages\django\template\base.py", line 170, in render
    return self._render(context)
  File "E:\Software\Code\Py_environment\lib\site-packages\django\template\base.py", line 162, in _render
    return self.nodelist.render(context)
  File "E:\Software\Code\Py_environment\lib\site-packages\django\template\base.py", line 938, in render
    bit = node.render_annotated(context)
  File "E:\Software\Code\Py_environment\lib\site-packages\django\template\base.py", line 905, in render_annotated
    return self.render(context)
  File "E:\Software\Code\Py_environment\lib\site-packages\django\template\loader_tags.py", line 150, in render
    return compiled_parent._render(context)
  File "E:\Software\Code\Py_environment\lib\site-packages\django\template\base.py", line 162, in _render
    return self.nodelist.render(context)
  File "E:\Software\Code\Py_environment\lib\site-packages\django\template\base.py", line 938, in render
    bit = node.render_annotated(context)
  File "E:\Software\Code\Py_environment\lib\site-packages\django\template\base.py", line 905, in render_annotated
    return self.render(context)
  File "E:\Software\Code\Py_environment\lib\site-packages\django\template\library.py", line 234, in render
    return t.render(new_context)
  File "E:\Software\Code\Py_environment\lib\site-packages\django\template\base.py", line 172, in render
    return self._render(context)
  File "E:\Software\Code\Py_environment\lib\site-packages\django\template\base.py", line 162, in _render
    return self.nodelist.render(context)
  File "E:\Software\Code\Py_environment\lib\site-packages\django\template\base.py", line 938, in render
    bit = node.render_annotated(context)
  File "E:\Software\Code\Py_environment\lib\site-packages\django\template\base.py", line 905, in render_annotated
    return self.render(context)
  File "E:\Software\Code\Py_environment\lib\site-packages\django\template\defaulttags.py", line 168, in render
    len_values = len(values)
  File "E:\Software\Code\Py_environment\lib\site-packages\django\db\models\query.py", line 262, in __len__
    self._fetch_all()
  File "E:\Software\Code\Py_environment\lib\site-packages\django\db\models\query.py", line 1324, in _fetch_all
    self._result_cache = list(self._iterable_class(self))
  File "E:\Software\Code\Py_environment\lib\site-packages\django\db\models\query.py", line 109, in __iter__
    for row in compiler.results_iter(chunked_fetch=self.chunked_fetch, chunk_size=self.chunk_size):
  File "E:\Software\Code\Py_environment\lib\site-packages\django\db\models\sql\compiler.py", line 1130, in results_iter
    results = self.execute_sql(MULTI, chunked_fetch=chunked_fetch, chunk_size=chunk_size)
  File "E:\Software\Code\Py_environment\lib\site-packages\django\db\models\sql\compiler.py", line 1175, in execute_sql
    cursor.execute(sql, params)
  File "E:\Software\Code\Py_environment\lib\site-packages\django\db\backends\utils.py", line 98, in execute
    return super().execute(sql, params)
  File "E:\Software\Code\Py_environment\lib\site-packages\django\db\backends\utils.py", line 66, in execute
    return self._execute_with_wrappers(sql, params, many=False, executor=self._execute)
  File "E:\Software\Code\Py_environment\lib\site-packages\django\db\backends\utils.py", line 75, in _execute_with_wrappers
    return executor(sql, params, many, context)
  File "E:\Software\Code\Py_environment\lib\site-packages\django\db\backends\utils.py", line 84, in _execute
    return self.cursor.execute(sql, params)
  File "E:\Software\Code\Py_environment\lib\site-packages\django\db\utils.py", line 90, in __exit__
    raise dj_exc_value.with_traceback(traceback) from exc_value
  File "E:\Software\Code\Py_environment\lib\site-packages\django\db\backends\utils.py", line 84, in _execute
    return self.cursor.execute(sql, params)
  File "E:\Software\Code\Py_environment\lib\site-packages\django\db\backends\sqlite3\base.py", line 423, in execute
    return Database.Cursor.execute(self, query, params)
django.db.utils.OperationalError: no such function: date_format
[2022-03-16 15:31:30,731][MainThread:12024][task_id:django.utils.autoreload][autoreload.py:637][INFO][Watching for file changes with StatReloader]
[2022-03-16 15:31:35,553][Thread-1:18744][task_id:django.request][log.py:224][WARNING][Not Found: /media/]
[2022-03-16 15:31:42,122][Thread-4:16640][task_id:django.request][log.py:224][WARNING][Not Found: /media/]
[2022-03-16 15:31:42,258][Thread-4:16640][task_id:django.request][log.py:224][WARNING][Not Found: /favicon.ico]
[2022-03-16 15:31:51,170][Thread-4:16640][task_id:django.request][log.py:224][WARNING][Not Found: /media/]
[2022-03-16 15:31:59,217][Thread-4:16640][task_id:django.request][log.py:224][WARNING][Not Found: /media/]
[2022-03-16 15:32:18,790][Thread-4:16640][task_id:django.request][log.py:224][WARNING][Not Found: /media/]
[2022-03-16 15:32:45,825][Thread-4:16640][task_id:django.request][log.py:224][WARNING][Not Found: /media/]
[2022-03-16 15:32:59,064][Thread-4:16640][task_id:django.request][log.py:224][WARNING][Not Found: /media/]
[2022-03-16 15:33:53,700][Thread-6:15336][task_id:django.request][log.py:224][WARNING][Not Found: /media/]
[2022-03-16 15:33:56,223][Thread-6:15336][task_id:django.request][log.py:224][WARNING][Not Found: /media/]
[2022-03-16 15:33:57,771][Thread-6:15336][task_id:django.request][log.py:224][ERROR][Internal Server Error: /blog/qq/]
Traceback (most recent call last):
  File "E:\Software\Code\Py_environment\lib\site-packages\django\db\backends\utils.py", line 84, in _execute
    return self.cursor.execute(sql, params)
  File "E:\Software\Code\Py_environment\lib\site-packages\django\db\backends\sqlite3\base.py", line 423, in execute
    return Database.Cursor.execute(self, query, params)
sqlite3.OperationalError: no such function: date_format

The above exception was the direct cause of the following exception:

Traceback (most recent call last):
  File "E:\Software\Code\Py_environment\lib\site-packages\django\core\handlers\exception.py", line 47, in inner
    response = get_response(request)
  File "E:\Software\Code\Py_environment\lib\site-packages\django\core\handlers\base.py", line 181, in _get_response
    response = wrapped_callback(request, *callback_args, **callback_kwargs)
  File "C:\Users\mi\Desktop\blog_one\blog\views.py", line 293, in home
    return render(request, "home.html", {
  File "E:\Software\Code\Py_environment\lib\site-packages\django\shortcuts.py", line 19, in render
    content = loader.render_to_string(template_name, context, request, using=using)
  File "E:\Software\Code\Py_environment\lib\site-packages\django\template\loader.py", line 62, in render_to_string
    return template.render(context, request)
  File "E:\Software\Code\Py_environment\lib\site-packages\django\template\backends\django.py", line 61, in render
    return self.template.render(context)
  File "E:\Software\Code\Py_environment\lib\site-packages\django\template\base.py", line 170, in render
    return self._render(context)
  File "E:\Software\Code\Py_environment\lib\site-packages\django\template\base.py", line 162, in _render
    return self.nodelist.render(context)
  File "E:\Software\Code\Py_environment\lib\site-packages\django\template\base.py", line 938, in render
    bit = node.render_annotated(context)
  File "E:\Software\Code\Py_environment\lib\site-packages\django\template\base.py", line 905, in render_annotated
    return self.render(context)
  File "E:\Software\Code\Py_environment\lib\site-packages\django\template\loader_tags.py", line 150, in render
    return compiled_parent._render(context)
  File "E:\Software\Code\Py_environment\lib\site-packages\django\template\base.py", line 162, in _render
    return self.nodelist.render(context)
  File "E:\Software\Code\Py_environment\lib\site-packages\django\template\base.py", line 938, in render
    bit = node.render_annotated(context)
  File "E:\Software\Code\Py_environment\lib\site-packages\django\template\base.py", line 905, in render_annotated
    return self.render(context)
  File "E:\Software\Code\Py_environment\lib\site-packages\django\template\library.py", line 234, in render
    return t.render(new_context)
  File "E:\Software\Code\Py_environment\lib\site-packages\django\template\base.py", line 172, in render
    return self._render(context)
  File "E:\Software\Code\Py_environment\lib\site-packages\django\template\base.py", line 162, in _render
    return self.nodelist.render(context)
  File "E:\Software\Code\Py_environment\lib\site-packages\django\template\base.py", line 938, in render
    bit = node.render_annotated(context)
  File "E:\Software\Code\Py_environment\lib\site-packages\django\template\base.py", line 905, in render_annotated
    return self.render(context)
  File "E:\Software\Code\Py_environment\lib\site-packages\django\template\defaulttags.py", line 168, in render
    len_values = len(values)
  File "E:\Software\Code\Py_environment\lib\site-packages\django\db\models\query.py", line 262, in __len__
    self._fetch_all()
  File "E:\Software\Code\Py_environment\lib\site-packages\django\db\models\query.py", line 1324, in _fetch_all
    self._result_cache = list(self._iterable_class(self))
  File "E:\Software\Code\Py_environment\lib\site-packages\django\db\models\query.py", line 109, in __iter__
    for row in compiler.results_iter(chunked_fetch=self.chunked_fetch, chunk_size=self.chunk_size):
  File "E:\Software\Code\Py_environment\lib\site-packages\django\db\models\sql\compiler.py", line 1130, in results_iter
    results = self.execute_sql(MULTI, chunked_fetch=chunked_fetch, chunk_size=chunk_size)
  File "E:\Software\Code\Py_environment\lib\site-packages\django\db\models\sql\compiler.py", line 1175, in execute_sql
    cursor.execute(sql, params)
  File "E:\Software\Code\Py_environment\lib\site-packages\django\db\backends\utils.py", line 98, in execute
    return super().execute(sql, params)
  File "E:\Software\Code\Py_environment\lib\site-packages\django\db\backends\utils.py", line 66, in execute
    return self._execute_with_wrappers(sql, params, many=False, executor=self._execute)
  File "E:\Software\Code\Py_environment\lib\site-packages\django\db\backends\utils.py", line 75, in _execute_with_wrappers
    return executor(sql, params, many, context)
  File "E:\Software\Code\Py_environment\lib\site-packages\django\db\backends\utils.py", line 84, in _execute
    return self.cursor.execute(sql, params)
  File "E:\Software\Code\Py_environment\lib\site-packages\django\db\utils.py", line 90, in __exit__
    raise dj_exc_value.with_traceback(traceback) from exc_value
  File "E:\Software\Code\Py_environment\lib\site-packages\django\db\backends\utils.py", line 84, in _execute
    return self.cursor.execute(sql, params)
  File "E:\Software\Code\Py_environment\lib\site-packages\django\db\backends\sqlite3\base.py", line 423, in execute
    return Database.Cursor.execute(self, query, params)
django.db.utils.OperationalError: no such function: date_format
[2022-03-16 15:43:28,477][MainThread:18080][task_id:django.utils.autoreload][autoreload.py:637][INFO][Watching for file changes with StatReloader]
[2022-03-16 15:43:30,455][Thread-1:8296][task_id:django.request][log.py:224][WARNING][Not Found: /media/]
[2022-03-16 15:43:32,144][Thread-1:8296][task_id:django.request][log.py:224][WARNING][Not Found: /media/]
[2022-03-16 15:43:33,960][Thread-1:8296][task_id:django.request][log.py:224][ERROR][Internal Server Error: /blog/qiqi/]
Traceback (most recent call last):
  File "E:\Software\Code\Py_environment\lib\site-packages\django\db\backends\utils.py", line 84, in _execute
    return self.cursor.execute(sql, params)
  File "E:\Software\Code\Py_environment\lib\site-packages\django\db\backends\sqlite3\base.py", line 423, in execute
    return Database.Cursor.execute(self, query, params)
sqlite3.OperationalError: no such function: date_format

The above exception was the direct cause of the following exception:

Traceback (most recent call last):
  File "E:\Software\Code\Py_environment\lib\site-packages\django\core\handlers\exception.py", line 47, in inner
    response = get_response(request)
  File "E:\Software\Code\Py_environment\lib\site-packages\django\core\handlers\base.py", line 181, in _get_response
    response = wrapped_callback(request, *callback_args, **callback_kwargs)
  File "C:\Users\mi\Desktop\blog_one\blog\views.py", line 293, in home
    return render(request, "home.html", {
  File "E:\Software\Code\Py_environment\lib\site-packages\django\shortcuts.py", line 19, in render
    content = loader.render_to_string(template_name, context, request, using=using)
  File "E:\Software\Code\Py_environment\lib\site-packages\django\template\loader.py", line 62, in render_to_string
    return template.render(context, request)
  File "E:\Software\Code\Py_environment\lib\site-packages\django\template\backends\django.py", line 61, in render
    return self.template.render(context)
  File "E:\Software\Code\Py_environment\lib\site-packages\django\template\base.py", line 170, in render
    return self._render(context)
  File "E:\Software\Code\Py_environment\lib\site-packages\django\template\base.py", line 162, in _render
    return self.nodelist.render(context)
  File "E:\Software\Code\Py_environment\lib\site-packages\django\template\base.py", line 938, in render
    bit = node.render_annotated(context)
  File "E:\Software\Code\Py_environment\lib\site-packages\django\template\base.py", line 905, in render_annotated
    return self.render(context)
  File "E:\Software\Code\Py_environment\lib\site-packages\django\template\loader_tags.py", line 150, in render
    return compiled_parent._render(context)
  File "E:\Software\Code\Py_environment\lib\site-packages\django\template\base.py", line 162, in _render
    return self.nodelist.render(context)
  File "E:\Software\Code\Py_environment\lib\site-packages\django\template\base.py", line 938, in render
    bit = node.render_annotated(context)
  File "E:\Software\Code\Py_environment\lib\site-packages\django\template\base.py", line 905, in render_annotated
    return self.render(context)
  File "E:\Software\Code\Py_environment\lib\site-packages\django\template\library.py", line 234, in render
    return t.render(new_context)
  File "E:\Software\Code\Py_environment\lib\site-packages\django\template\base.py", line 172, in render
    return self._render(context)
  File "E:\Software\Code\Py_environment\lib\site-packages\django\template\base.py", line 162, in _render
    return self.nodelist.render(context)
  File "E:\Software\Code\Py_environment\lib\site-packages\django\template\base.py", line 938, in render
    bit = node.render_annotated(context)
  File "E:\Software\Code\Py_environment\lib\site-packages\django\template\base.py", line 905, in render_annotated
    return self.render(context)
  File "E:\Software\Code\Py_environment\lib\site-packages\django\template\defaulttags.py", line 168, in render
    len_values = len(values)
  File "E:\Software\Code\Py_environment\lib\site-packages\django\db\models\query.py", line 262, in __len__
    self._fetch_all()
  File "E:\Software\Code\Py_environment\lib\site-packages\django\db\models\query.py", line 1324, in _fetch_all
    self._result_cache = list(self._iterable_class(self))
  File "E:\Software\Code\Py_environment\lib\site-packages\django\db\models\query.py", line 109, in __iter__
    for row in compiler.results_iter(chunked_fetch=self.chunked_fetch, chunk_size=self.chunk_size):
  File "E:\Software\Code\Py_environment\lib\site-packages\django\db\models\sql\compiler.py", line 1130, in results_iter
    results = self.execute_sql(MULTI, chunked_fetch=chunked_fetch, chunk_size=chunk_size)
  File "E:\Software\Code\Py_environment\lib\site-packages\django\db\models\sql\compiler.py", line 1175, in execute_sql
    cursor.execute(sql, params)
  File "E:\Software\Code\Py_environment\lib\site-packages\django\db\backends\utils.py", line 98, in execute
    return super().execute(sql, params)
  File "E:\Software\Code\Py_environment\lib\site-packages\django\db\backends\utils.py", line 66, in execute
    return self._execute_with_wrappers(sql, params, many=False, executor=self._execute)
  File "E:\Software\Code\Py_environment\lib\site-packages\django\db\backends\utils.py", line 75, in _execute_with_wrappers
    return executor(sql, params, many, context)
  File "E:\Software\Code\Py_environment\lib\site-packages\django\db\backends\utils.py", line 84, in _execute
    return self.cursor.execute(sql, params)
  File "E:\Software\Code\Py_environment\lib\site-packages\django\db\utils.py", line 90, in __exit__
    raise dj_exc_value.with_traceback(traceback) from exc_value
  File "E:\Software\Code\Py_environment\lib\site-packages\django\db\backends\utils.py", line 84, in _execute
    return self.cursor.execute(sql, params)
  File "E:\Software\Code\Py_environment\lib\site-packages\django\db\backends\sqlite3\base.py", line 423, in execute
    return Database.Cursor.execute(self, query, params)
django.db.utils.OperationalError: no such function: date_format
[2022-03-16 16:32:13,388][Thread-3:10700][task_id:django.request][log.py:224][WARNING][Not Found: /media/]
[2022-03-16 16:32:13,513][Thread-3:10700][task_id:django.request][log.py:224][WARNING][Not Found: /favicon.ico]
[2022-03-16 16:32:29,096][Thread-3:10700][task_id:django.request][log.py:224][WARNING][Not Found: /media/]
[2022-03-16 16:32:29,155][Thread-3:10700][task_id:django.request][log.py:224][WARNING][Not Found: /media/]
[2022-03-18 21:46:12,799][MainThread:18032][task_id:django.utils.autoreload][autoreload.py:637][INFO][Watching for file changes with StatReloader]
[2022-03-18 21:46:18,148][Thread-2:4452][task_id:django.request][log.py:224][WARNING][Not Found: /media/]
[2022-03-18 21:46:18,282][Thread-2:4452][task_id:django.request][log.py:224][WARNING][Not Found: /favicon.ico]
[2022-03-18 21:46:35,733][Thread-1:13140][task_id:django.request][log.py:224][WARNING][Not Found: /media/]
[2022-03-18 21:47:01,000][Thread-1:13140][task_id:django.request][log.py:224][WARNING][Not Found: /media/]
[2022-03-18 21:47:06,291][Thread-1:13140][task_id:django.request][log.py:224][ERROR][Internal Server Error: /blog/qiqi/]
Traceback (most recent call last):
  File "E:\Software\Code\Py_environment\lib\site-packages\django\db\backends\utils.py", line 84, in _execute
    return self.cursor.execute(sql, params)
  File "E:\Software\Code\Py_environment\lib\site-packages\django\db\backends\sqlite3\base.py", line 423, in execute
    return Database.Cursor.execute(self, query, params)
sqlite3.OperationalError: no such function: date_format

The above exception was the direct cause of the following exception:

Traceback (most recent call last):
  File "E:\Software\Code\Py_environment\lib\site-packages\django\core\handlers\exception.py", line 47, in inner
    response = get_response(request)
  File "E:\Software\Code\Py_environment\lib\site-packages\django\core\handlers\base.py", line 181, in _get_response
    response = wrapped_callback(request, *callback_args, **callback_kwargs)
  File "C:\Users\mi\Desktop\blog_one\blog\views.py", line 293, in home
    return render(request, "home.html", {
  File "E:\Software\Code\Py_environment\lib\site-packages\django\shortcuts.py", line 19, in render
    content = loader.render_to_string(template_name, context, request, using=using)
  File "E:\Software\Code\Py_environment\lib\site-packages\django\template\loader.py", line 62, in render_to_string
    return template.render(context, request)
  File "E:\Software\Code\Py_environment\lib\site-packages\django\template\backends\django.py", line 61, in render
    return self.template.render(context)
  File "E:\Software\Code\Py_environment\lib\site-packages\django\template\base.py", line 170, in render
    return self._render(context)
  File "E:\Software\Code\Py_environment\lib\site-packages\django\template\base.py", line 162, in _render
    return self.nodelist.render(context)
  File "E:\Software\Code\Py_environment\lib\site-packages\django\template\base.py", line 938, in render
    bit = node.render_annotated(context)
  File "E:\Software\Code\Py_environment\lib\site-packages\django\template\base.py", line 905, in render_annotated
    return self.render(context)
  File "E:\Software\Code\Py_environment\lib\site-packages\django\template\loader_tags.py", line 150, in render
    return compiled_parent._render(context)
  File "E:\Software\Code\Py_environment\lib\site-packages\django\template\base.py", line 162, in _render
    return self.nodelist.render(context)
  File "E:\Software\Code\Py_environment\lib\site-packages\django\template\base.py", line 938, in render
    bit = node.render_annotated(context)
  File "E:\Software\Code\Py_environment\lib\site-packages\django\template\base.py", line 905, in render_annotated
    return self.render(context)
  File "E:\Software\Code\Py_environment\lib\site-packages\django\template\library.py", line 234, in render
    return t.render(new_context)
  File "E:\Software\Code\Py_environment\lib\site-packages\django\template\base.py", line 172, in render
    return self._render(context)
  File "E:\Software\Code\Py_environment\lib\site-packages\django\template\base.py", line 162, in _render
    return self.nodelist.render(context)
  File "E:\Software\Code\Py_environment\lib\site-packages\django\template\base.py", line 938, in render
    bit = node.render_annotated(context)
  File "E:\Software\Code\Py_environment\lib\site-packages\django\template\base.py", line 905, in render_annotated
    return self.render(context)
  File "E:\Software\Code\Py_environment\lib\site-packages\django\template\defaulttags.py", line 168, in render
    len_values = len(values)
  File "E:\Software\Code\Py_environment\lib\site-packages\django\db\models\query.py", line 262, in __len__
    self._fetch_all()
  File "E:\Software\Code\Py_environment\lib\site-packages\django\db\models\query.py", line 1324, in _fetch_all
    self._result_cache = list(self._iterable_class(self))
  File "E:\Software\Code\Py_environment\lib\site-packages\django\db\models\query.py", line 109, in __iter__
    for row in compiler.results_iter(chunked_fetch=self.chunked_fetch, chunk_size=self.chunk_size):
  File "E:\Software\Code\Py_environment\lib\site-packages\django\db\models\sql\compiler.py", line 1130, in results_iter
    results = self.execute_sql(MULTI, chunked_fetch=chunked_fetch, chunk_size=chunk_size)
  File "E:\Software\Code\Py_environment\lib\site-packages\django\db\models\sql\compiler.py", line 1175, in execute_sql
    cursor.execute(sql, params)
  File "E:\Software\Code\Py_environment\lib\site-packages\django\db\backends\utils.py", line 98, in execute
    return super().execute(sql, params)
  File "E:\Software\Code\Py_environment\lib\site-packages\django\db\backends\utils.py", line 66, in execute
    return self._execute_with_wrappers(sql, params, many=False, executor=self._execute)
  File "E:\Software\Code\Py_environment\lib\site-packages\django\db\backends\utils.py", line 75, in _execute_with_wrappers
    return executor(sql, params, many, context)
  File "E:\Software\Code\Py_environment\lib\site-packages\django\db\backends\utils.py", line 84, in _execute
    return self.cursor.execute(sql, params)
  File "E:\Software\Code\Py_environment\lib\site-packages\django\db\utils.py", line 90, in __exit__
    raise dj_exc_value.with_traceback(traceback) from exc_value
  File "E:\Software\Code\Py_environment\lib\site-packages\django\db\backends\utils.py", line 84, in _execute
    return self.cursor.execute(sql, params)
  File "E:\Software\Code\Py_environment\lib\site-packages\django\db\backends\sqlite3\base.py", line 423, in execute
    return Database.Cursor.execute(self, query, params)
django.db.utils.OperationalError: no such function: date_format
[2022-03-18 21:47:27,304][Thread-1:13140][task_id:django.request][log.py:224][ERROR][Internal Server Error: /blog/qq/]
Traceback (most recent call last):
  File "E:\Software\Code\Py_environment\lib\site-packages\django\db\backends\utils.py", line 84, in _execute
    return self.cursor.execute(sql, params)
  File "E:\Software\Code\Py_environment\lib\site-packages\django\db\backends\sqlite3\base.py", line 423, in execute
    return Database.Cursor.execute(self, query, params)
sqlite3.OperationalError: no such function: date_format

The above exception was the direct cause of the following exception:

Traceback (most recent call last):
  File "E:\Software\Code\Py_environment\lib\site-packages\django\core\handlers\exception.py", line 47, in inner
    response = get_response(request)
  File "E:\Software\Code\Py_environment\lib\site-packages\django\core\handlers\base.py", line 181, in _get_response
    response = wrapped_callback(request, *callback_args, **callback_kwargs)
  File "C:\Users\mi\Desktop\blog_one\blog\views.py", line 293, in home
    return render(request, "home.html", {
  File "E:\Software\Code\Py_environment\lib\site-packages\django\shortcuts.py", line 19, in render
    content = loader.render_to_string(template_name, context, request, using=using)
  File "E:\Software\Code\Py_environment\lib\site-packages\django\template\loader.py", line 62, in render_to_string
    return template.render(context, request)
  File "E:\Software\Code\Py_environment\lib\site-packages\django\template\backends\django.py", line 61, in render
    return self.template.render(context)
  File "E:\Software\Code\Py_environment\lib\site-packages\django\template\base.py", line 170, in render
    return self._render(context)
  File "E:\Software\Code\Py_environment\lib\site-packages\django\template\base.py", line 162, in _render
    return self.nodelist.render(context)
  File "E:\Software\Code\Py_environment\lib\site-packages\django\template\base.py", line 938, in render
    bit = node.render_annotated(context)
  File "E:\Software\Code\Py_environment\lib\site-packages\django\template\base.py", line 905, in render_annotated
    return self.render(context)
  File "E:\Software\Code\Py_environment\lib\site-packages\django\template\loader_tags.py", line 150, in render
    return compiled_parent._render(context)
  File "E:\Software\Code\Py_environment\lib\site-packages\django\template\base.py", line 162, in _render
    return self.nodelist.render(context)
  File "E:\Software\Code\Py_environment\lib\site-packages\django\template\base.py", line 938, in render
    bit = node.render_annotated(context)
  File "E:\Software\Code\Py_environment\lib\site-packages\django\template\base.py", line 905, in render_annotated
    return self.render(context)
  File "E:\Software\Code\Py_environment\lib\site-packages\django\template\library.py", line 234, in render
    return t.render(new_context)
  File "E:\Software\Code\Py_environment\lib\site-packages\django\template\base.py", line 172, in render
    return self._render(context)
  File "E:\Software\Code\Py_environment\lib\site-packages\django\template\base.py", line 162, in _render
    return self.nodelist.render(context)
  File "E:\Software\Code\Py_environment\lib\site-packages\django\template\base.py", line 938, in render
    bit = node.render_annotated(context)
  File "E:\Software\Code\Py_environment\lib\site-packages\django\template\base.py", line 905, in render_annotated
    return self.render(context)
  File "E:\Software\Code\Py_environment\lib\site-packages\django\template\defaulttags.py", line 168, in render
    len_values = len(values)
  File "E:\Software\Code\Py_environment\lib\site-packages\django\db\models\query.py", line 262, in __len__
    self._fetch_all()
  File "E:\Software\Code\Py_environment\lib\site-packages\django\db\models\query.py", line 1324, in _fetch_all
    self._result_cache = list(self._iterable_class(self))
  File "E:\Software\Code\Py_environment\lib\site-packages\django\db\models\query.py", line 109, in __iter__
    for row in compiler.results_iter(chunked_fetch=self.chunked_fetch, chunk_size=self.chunk_size):
  File "E:\Software\Code\Py_environment\lib\site-packages\django\db\models\sql\compiler.py", line 1130, in results_iter
    results = self.execute_sql(MULTI, chunked_fetch=chunked_fetch, chunk_size=chunk_size)
  File "E:\Software\Code\Py_environment\lib\site-packages\django\db\models\sql\compiler.py", line 1175, in execute_sql
    cursor.execute(sql, params)
  File "E:\Software\Code\Py_environment\lib\site-packages\django\db\backends\utils.py", line 98, in execute
    return super().execute(sql, params)
  File "E:\Software\Code\Py_environment\lib\site-packages\django\db\backends\utils.py", line 66, in execute
    return self._execute_with_wrappers(sql, params, many=False, executor=self._execute)
  File "E:\Software\Code\Py_environment\lib\site-packages\django\db\backends\utils.py", line 75, in _execute_with_wrappers
    return executor(sql, params, many, context)
  File "E:\Software\Code\Py_environment\lib\site-packages\django\db\backends\utils.py", line 84, in _execute
    return self.cursor.execute(sql, params)
  File "E:\Software\Code\Py_environment\lib\site-packages\django\db\utils.py", line 90, in __exit__
    raise dj_exc_value.with_traceback(traceback) from exc_value
  File "E:\Software\Code\Py_environment\lib\site-packages\django\db\backends\utils.py", line 84, in _execute
    return self.cursor.execute(sql, params)
  File "E:\Software\Code\Py_environment\lib\site-packages\django\db\backends\sqlite3\base.py", line 423, in execute
    return Database.Cursor.execute(self, query, params)
django.db.utils.OperationalError: no such function: date_format
[2022-03-18 21:47:55,321][Thread-1:13140][task_id:django.request][log.py:224][WARNING][Not Found: /media/]
